Workbook

Sheet Assumptions
A1: MODEL ASSUMPTIONS
A2: Blue = input | Green = linked value | Black = calculation | Yellow = verify
A3: GENERAL
A4: Analysis start year | B4: 2026 | C4: Fiscal Year 1 (October 2026 to September 2027)
A5: Season start date | B5: 46296
A6: Currency | B6: AED
A8: DEMAND ASSUMPTIONS
A9: FY1 event pipeline count | B9: =COUNTA('FY1 Event Pipeline'!A4:A15) -> 12 | C9: From 'FY1 Event Pipeline' sheet
A10: Target coverage of peak concurrency - Cabins | B10: 0.85 | C10: Percentile of probability-adjusted peak owned in fleet
A11: Target coverage of peak concurrency - Buggies | B11: 0.5
A12: Target coverage of peak concurrency - Barriers | B12: 0.85
A13: Target coverage of peak concurrency - Fencing | B13: 0.85
A14: Target coverage of peak concurrency - Terratrak | B14: 0.85
A15: Events % growth YoY | B15: 0.1 | C15: - 10% growth in annual events - conservative assumption for outdoor festivals, concerts, and public-events (projected 10-16% CAGR). - Growth rate drives peak concurrency (thus fleet growth) & cabin-days deployed
A17: REVENUE - RENTAL RATES (DAILY)
A18: Revenue per cabin per day | B18: 350 | C18: approx. 10,000/30 day event rate rounded up as peak daily rate
A19: Revenue per buggy per day | B19: 700 | C19: Daily rental rate from original model (ensure this isn't rented out in weekly slabs)
A20: Revenue per barrier per day | B20: =12/30 -> 0.4 | C20: AED 0.4/day rate per barrier - monthly-slab rental @ AED 12/barrier/month
A21: Revenue per fencing per day | B21: =55/30 -> 1.8333333 | C21: AED 1.83/day rate per fencing - monthly-slab rental @ AED 55/fence/month
A22: Revenue per flooring per day | B22: =900/30 -> 30 | C22: AED 30/day rate per flooring - monthly-slab rental @ AED 900/floor/month
C23: Rental Rate Growth?
A25: CAPEX
A26: Cabin useful life (years) | B26: 8 | C26: 8 years, straight-line
A27: Cabin residual value (% of CapEx) | B27: 0.2 | C27: 20% residual at end of useful life
A28: Cabin annual maintenance (% of CapEx p.a.) | B28: 0.025 | C28: 2.5% of gross capex
A29: Buggie cost per unit | B29: 40000 | C29: Avg. all-in cost
A30: Buggie useful life (years) | B30: 10 | C30: 10 years, straight-line
A31: Buggie residual value (% of CapEx) | B31: 0.3 | C31: 30% residual at end of useful life
A32: Buggie annual maintenance (% of CapEx p.a.) | B32: 0.025 | C32: 2.5% of gross capex
A33: Barrier cost per unit | B33: 300 | C33: Avg. all-in cost
A34: Fencing cost per unit | B34: 400 | C34: Avg. all-in cost
A35: Barriers & Fencing useful life (years) | B35: 10 | C35: 10 years, straight-line
A36: Barriers & Fencing residual value (% of CapEx) | B36: 0.4 | C36: 40% residual at end of useful life
A37: Barriers & Fencing annual maintenance (% of CapEx p.a.) | B37: 0.005 | C37: 0.5% of gross capex
... A42: Material cost inflation | B42: 0.02 | C42: 2.0% Y-o-Y unit price escalation
A44: OPEX / OVERHEAD
A45: Cabin Storage Yard Rental | B45: 20 | C45: Price (AED) per sqft per year
A46: % Circulation
A47: Hot desk rent / head / month | B47: 2000 | C47: Avg. cost of a fixed seat in a shared, coworking environment.
A48: Marketing budget per month | B48: 10000
...

Sheet FY1 Event Pipeline
A1: FINANCIAL YEAR 1 EVENT PIPELINE
A2: List of all the events in the FY 2026-2027 pipeline | Model assumes all assets are on hire upon delivery at mobilization start date until the demobilization end date | The events and asset demand form the basis for the demand distribution
A3: Event | B3: Venue | C3: Win Rate | D3: Live Open | E3: Live Close | F3: Days Live | G3: Days Mob | H3: Mob Start | I3: Days Demob | J3: Demob End | K3: Paid Hire Days | L3: Monthly-Slabs | M3: Weekly-Slabs | N3: Cabins | O3: Buggies | P3: Barriers | Q3: Fencing | R3: Terratrak | S3: Python Tuple Input
A4: Saadiyat Nights | B4: Saadiyat Island open-air | C4: 0.5 | D4: 46327 | E4: 46446 | F4: =E4-D4+1 -> 120 | G4: 30 | H4: =D4-G4 -> 46297 | I4: 7 | J4: =E4+I4 -> 46453 | K4: =J4-H4+1 -> 157 | L4: =_xlfn.CEILING.MATH(K4/30,1) -> 6 | M4: =_xlfn.CEILING.MATH(K4/7,1) -> 23 | N4: 10 | O4: 10 | P4: 0 | Q4: 0 | R4: 280 | S4: =_xlfn.CONCAT("('",,A4,"',",C4,",",H4-$B$17,",",J4-$B$17,",",N4,",",O4,",",P4,",",Q4,",",R4,"),") -> ('Saadiyat Nights',0.5,1,157,10,10,0,0,280),
A5: BRED X | B5: Yas Marina Circuit / TBC | C5: 0.5 | D5: 46332 | E5: 46336 | F5: =E5-D5+1 -> 5 | G5: 14 | H5: =D5-G5 -> 46318 | I5: 3 | J5: =E5+I5 -> 46339 | K5: =J5-H5+1 -> 22 | L5: =_xlfn.CEILING.MATH(K5/30,1) -> 1 | M5: =_xlfn.CEILING.MATH(K5/7,1) -> 4 | N5: 8 | O5: 0 | P5: 0 | Q5: 0 | R5: 0 | S5: =_xlfn.CONCAT("('",,A5,"',",C5,",",H5-$B$17,",",J5-$B$17,",",N5,",",O5,",",P5,",",Q5,",",R5,"),") -> ('BRED X',0.5,22,43,8,0,0,0,0),
A6: MOTN DHA | B6: Al Dhafra | C6: 0.5 | D6: 46344 | E6: 46349 | F6: =E6-D6+1 -> 6 | G6: 14 | H6: =D6-G6 -> 46330 | I6: 3 | J6: =E6+I6 -> 46352 | K6: =J6-H6+1 -> 23 | L6: =_xlfn.CEILING.MATH(K6/30,1) -> 1 | M6: =_xlfn.CEILING.MATH(K6/7,1) -> 4 | N6: 8 | O6: 6 | P6: 350 | Q6: 550 | R6: 0 | S6: =_xlfn.CONCAT("('",,A6,"',",C6,",",H6-$B$17,",",J6-$B$17,",",N6,",",O6,",",P6,",",Q6,",",R6,"),") -> ('MOTN DHA',0.5,34,56,8,6,350,550,0),
A7: No Art UAE | B7: Saadiyat Island / TBC | C7: 0.5 | D7: 46346 | E7: 46350 | F7: =E7-D7+1 -> 5 | G7: 14 | H7: =D7-G7 -> 46332 | I7: 3 | J7: =E7+I7 -> 46353 | K7: =J7-H7+1 -> 22 | L7: =_xlfn.CEILING.MATH(K7/30,1) -> 1 | M7: =_xlfn.CEILING.MATH(K7/7,1) -> 4 | N7: 24 | O7: 6 | P7: 0 | Q7: 0 | R7: 200 | S7: =_xlfn.CONCAT("('",,A7,"',",C7,",",H7-$B$17,",",J7-$B$17,",",N7,",",O7,",",P7,",",Q7,",",R7,"),") -> ('No Art UAE',0.5,36,57,24,6,0,0,200),
A8: Tanweer Festival | B8: Mleiha Desert, Sharjah | C8: 0.5 | D8: 46347 | E8: 46349 | F8: =E8-D8+1 -> 3 | G8: 7 | H8: =D8-G8 -> 46340 | I8: 3 | J8: =E8+I8 -> 46352 | K8: =J8-H8+1 -> 13 | L8: =_xlfn.CEILING.MATH(K8/30,1) -> 1 | M8: =_xlfn.CEILING.MATH(K8/7,1) -> 2 | N8: 0 | O8: 8 | P8: 900 | Q8: 50 | R8: 200 | S8: =_xlfn.CONCAT("('",,A8,"',",C8,",",H8-$B$17,",",J8-$B$17,",",N8,",",O8,",",P8,",",Q8,",",R8,"),") -> ('Tanweer Festival',0.5,44,56,0,8,900,50,200),
A9: MOTN AAN | B9: Al Ain | C9: 0.5 | D9: 46350 | E9: 46358 | F9: =E9-D9+1 -> 9 | G9: 14 | H9: =D9-G9 -> 46336 | I9: 4 | J9: =E9+I9 -> 46362 | K9: =J9-H9+1 -> 27 | L9: =_xlfn.CEILING.MATH(K9/30,1) -> 1 | M9: =_xlfn.CEILING.MATH(K9/7,1) -> 4 | N9: 18 | O9: 6 | P9: 350 | Q9: 550 | R9: 0 | S9: =_xlfn.CONCAT("('",,A9,"',",C9,",",H9-$B$17,",",J9-$B$17,",",N9,",",O9,",",P9,",",Q9,",",R9,"),") -> ('MOTN AAN',0.5,40,66,18,6,350,550,0),
A10: F1 Afterparty | B10: Yas Marina Circuit, Yas Island | C10: 0.5 | D10: 46360 | E10: 46362 | F10: =E10-D10+1 -> 3 | G10: 7 | H10: =D10-G10 -> 46353 | I10: 3 | J10: =E10+I10 -> 46365 | K10: =J10-H10+1 -> 13 | L10: =_xlfn.CEILING.MATH(K10/30,1) -> 1 | M10: =_xlfn.CEILING.MATH(K10/7,1) -> 2 | N10: 29 | O10: 8 | P10: 714 | Q10: 1180 | R10: 178 | S10: =_xlfn.CONCAT("('",,A10,"',",C10,",",H10-$B$17,",",J10-$B$17,",",N10,",",O10,",",P10,",",Q10,",",R10,"),") -> ('F1 Afterparty',0.5,57,69,29,8,714,1180,178),
A11: MOTN AUH | B11: Abu Dhabi Corniche | C11: 0.5 | D11: 46366 | E11: 46391 | F11: =E11-D11+1 -> 26 | G11: 20 | H11: =D11-G11 -> 46346 | I11: 7 | J11: =E11+I11 -> 46398 | K11: =J11-H11+1 -> 53 | L11: =_xlfn.CEILING.MATH(K11/30,1) -> 2 | M11: =_xlfn.CEILING.MATH(K11/7,1) -> 8 | N11: 20 | O11: 10 | P11: 700 | Q11: 1100 | R11: 200 | S11: =_xlfn.CONCAT("('",,A11,"',",C11,",",H11-$B$17,",",J11-$B$17,",",N11,",",O11,",",P11,",",Q11,",",R11,"),") -> ('MOTN AUH',0.5,50,102,20,10,700,1100,200),
A12: Yas Winterfest | B12: Yas Gateway Park, Yas Island | C12: 0.5 | D12: 46367 | E12: 46377 | F12: =E12-D12+1 -> 11 | G12: 15 | H12: =D12-G12 -> 46352 | I12: 7 | J12: =E12+I12 -> 46384 | K12: =J12-H12+1 -> 33 | L12: =_xlfn.CEILING.MATH(K12/30,1) -> 2 | M12: =_xlfn.CEILING.MATH(K12/7,1) -> 5 | N12: 6 | O12: 4 | P12: 644 | Q12: 760 | R12: 60 | S12: =_xlfn.CONCAT("('",,A12,"',",C12,",",H12-$B$17,",",J12-$B$17,",",N12,",",O12,",",P12,",",Q12,",",R12,"),") -> ('Yas Winterfest',0.5,56,88,6,4,644,760,60),
A13: Animenia | B13: Manarat Al Saadiyat | C13: 0.5 | D13: 46429 | E13: 46433 | F13: =E13-D13+1 -> 5 | G13: 15 | H13: =D13-G13 -> 46414 | I13: 3 | J13: =E13+I13 -> 46436 | K13: =J13-H13+1 -> 23 | L13: =_xlfn.CEILING.MATH(K13/30,1) -> 1 | M13: =_xlfn.CEILING.MATH(K13/7,1) -> 4 | N13: 8 | O13: 4 | P13: 288 | Q13: 192 | R13: 0 | S13: =_xlfn.CONCAT("('",,A13,"',",C13,",",H13-$B$17,",",J13-$B$17,",",N13,",",O13,",",P13,",",Q13,",",R13,"),") -> ('Animenia',0.5,118,140,8,4,288,192,0),
A14: DAZ | B14: Al Jahili Park, Al Ain | C14: 0.5 | D14: 46480 | E14: 46489 | F14: =E14-D14+1 -> 10 | G14: 14 | H14: =D14-G14 -> 46466 | I14: 7 | J14: =E14+I14 -> 46496 | K14: =J14-H14+1 -> 31 | L14: =_xlfn.CEILING.MATH(K14/30,1) -> 2 | M14: =_xlfn.CEILING.MATH(K14/7,1) -> 5 | N14: 15 | O14: 4 | P14: 775 | Q14: 225 | R14: 60 | S14: =_xlfn.CONCAT("('",,A14,"',",C14,",",H14-$B$17,",",J14-$B$17,",",N14,",",O14,",",P14,",",Q14,",",R14,"),") -> ('DAZ',0.5,170,200,15,4,775,225,60),
A15: BRED | B15: Yas Marina Circuit, Yas Island | C15: 0.5 | D15: 46499 | E15: 46503 | F15: =E15-D15+1 -> 5 | G15: 7 | H15: =D15-G15 -> 46492 | I15: 3 | J15: =E15+I15 -> 46506 | K15: =J15-H15+1 -> 15 | L15: =_xlfn.CEILING.MATH(K15/30,1) -> 1 | M15: =_xlfn.CEILING.MATH(K15/7,1) -> 3 | N15: 22 | O15: 6 | P15: 1500 | Q15: 500 | R15: 0 | S15: =_xlfn.CONCAT("('",,A15,"',",C15,",",H15-$B$17,",",J15-$B$17,",",N15,",",O15,",",P15,",",Q15,",",R15,"),") -> ('BRED',0.5,196,210,22,6,1500,500,0),
M16: Mean | N16: =AVERAGE(N4:N15) -> 14 | O16: =AVERAGE(O4:O15) -> 6 | P16: =AVERAGE(P4:P15) -> 518.41667 | Q16: =AVERAGE(Q4:Q15) -> 425.58333 | R16: =AVERAGE(R4:R15) -> 98.166667
A17: Calendar Start | B17: =Assumptions!B5 -> 46296 | M17: Median | N17: =MEDIAN(N4:N15) -> 12.5 | O17: =MEDIAN(O4:O15) -> 6 | P17: =MEDIAN(P4:P15) -> 497 | Q17: =MEDIAN(Q4:Q15) -> 362.5 | R17: =MEDIAN(R4:R15) -> 60
A19: FY1 (2026-2027) Concurrent Demand Curve

Sheet Human Resources
A1: HUMAN RESOURCES
A2: Personnel Count
A3: Position | D3: Year 1 | E3: Year 2 | F3: Year 3 | G3: Year 4 | H3: Year 5 | I3: Year 6 | J3: Year 7 | K3: Year 8
A4: General Manager (to hire) | D4: 1 | E4: 1 | F4: 1 | G4: 1 | H4: 1 | I4: 1 | J4: 1 | K4: 1
A5: Sales Manager | D5: 1 | E5: 1 | F5: 1 | G5: 1 | H5: 1 | I5: 1 | J5: 1 | K5: 1
A6: Accountant | D6: 1 | E6: 1 | F6: 1 | G6: 1 | H6: 1 | I6: 1 | J6: 1 | K6: 1
A7: Operations Manager | D7: 1 | E7: 1 | F7: 1 | G7: 1 | H7: 1 | I7: 1 | J7: 1 | K7: 1
A8: Plumber | D8: 1 | E8: 1 | F8: 2 | G8: 2 | H8: 3 | I8: 3 | J8: 4 | K8: 4
A9: Electrician | D9: 1 | E9: 1 | F9: 2 | G9: 2 | H9: 3 | I9: 3 | J9: 4 | K9: 4
A10: Admin | D10: 1 | E10: 1 | F10: 1 | G10: 1 | H10: 1 | I10: 2 | J10: 2 | K10: 2
A12: Salary/Personnel
A13: Position | B13: Monthly | C13: % Esc. | D13: Year 1 | E13: Year 2 | F13: Year 3 | G13: Year 4 | H13: Year 5 | I13: Year 6 | J13: Year 7 | K13: Year 8
A14: General Manager (to hire) | D14: 0 | E14: 0 | F14: 0 | G14: 0 | H14: 0 | I14: 0 | J14: 0 | K14: 0
A15: Sales Manager | B15: 12000 | C15: 0.1 | D15: =B15*12 -> 144000 | E15: =D15*(1+$C15) -> 158400 | F15: =E15*(1+$C15) -> 174240 | G15: =F15*(1+$C15) -> 191664 | H15: =G15*(1+$C15) -> 210830.4 | I15: =H15*(1+$C15) -> 231913.44 | J15: =I15*(1+$C15) -> 255104.78 | K15: =J15*(1+$C15) -> 280615.26
A16: Accountant | B16: 5000 | C16: 0.1 | D16: =B16*12 -> 60000 | E16: =D16*(1+$C16) -> 66000 | F16: =E16*(1+$C16) -> 72600 | G16: =F16*(1+$C16) -> 79860 | H16: =G16*(1+$C16) -> 87846 | I16: =H16*(1+$C16) -> 96630.6 | J16: =I16*(1+$C16) -> 106293.66 | K16: =J16*(1+$C16) -> 116923.03
A17: Operations Manager | B17: 12000 | C17: 0.1 | D17: =B17*12 -> 144000 | E17: =D17*(1+$C17) -> 158400 | F17: =E17*(1+$C17) -> 174240 | G17: =F17*(1+$C17) -> 191664 | H17: =G17*(1+$C17) -> 210830.4 | I17: =H17*(1+$C17) -> 231913.44 | J17: =I17*(1+$C17) -> 255104.78 | K17: =J17*(1+$C17) -> 280615.26
A18: Plumber | B18: 4000 | C18: 0.05 | D18: =B18*12 -> 48000 | E18: =D18*(1+$C18) -> 50400 | F18: =E18*(1+$C18) -> 52920 | G18: =F18*(1+$C18) -> 55566 | H18: =G18*(1+$C18) -> 58344.3 | I18: =H18*(1+$C18) -> 61261.515 | J18: =I18*(1+$C18) -> 64324.591 | K18: =J18*(1+$C18) -> 67540.82
A19: Electrician | B19: 4000 | C19: 0.05 | D19: =B19*12 -> 48000 | E19: =D19*(1+$C19) -> 50400 | F19: =E19*(1+$C19) -> 52920 | G19: =F19*(1+$C19) -> 55566 | H19: =G19*(1+$C19) -> 58344.3 | I19: =H19*(1+$C19) -> 61261.515 | J19: =I19*(1+$C19) -> 64324.591 | K19: =J19*(1+$C19) -> 67540.82
A20: Admin | B20: 4000 | C20: 0.05 | D20: =B20*12 -> 48000 | E20: =D20*(1+$C20) -> 50400 | F20: =E20*(1+$C20) -> 52920 | G20: =F20*(1+$C20) -> 55566 | H20: =G20*(1+$C20) -> 58344.3 | I20: =H20*(1+$C20) -> 61261.515 | J20: =I20*(1+$C20) -> 64324.591 | K20: =J20*(1+$C20) -> 67540.82
A22: Total Salary
A23: Position | D23: Year 1 | E23: Year 2 | F23: Year 3 | G23: Year 4 | H23: Year 5 | I23: Year 6 | J23: Year 7 | K23: Year 8
A24: General Manager (to hire) | D24: =D4*D14 -> 0 | E24: =E4*E14 -> 0 | F24: =F4*F14 -> 0 | G24: =G4*G14 -> 0 | H24: =H4*H14 -> 0 | I24: =I4*I14 -> 0 | J24: =J4*J14 -> 0 | K24: =K4*K14 -> 0
A25: Sales Manager | D25: =D5*D15 -> 144000 | E25: =E5*E15 -> 158400 | F25: =F5*F15 -> 174240 | G25: =G5*G15 -> 191664 | H25: =H5*H15 -> 210830.4 | I25: =I5*I15 -> 231913.44 | J25: =J5*J15 -> 255104.78 | K25: =K5*K15 -> 280615.26
A26: Accountant | D26: =D6*D16 -> 60000 | E26: =E6*E16 -> 66000 | F26: =F6*F16 -> 72600 | G26: =G6*G16 -> 79860 | H26: =H6*H16 -> 87846 | I26: =I6*I16 -> 96630.6 | J26: =J6*J16 -> 106293.66 | K26: =K6*K16 -> 116923.03
A27: Operations Manager | D27: =D7*D17 -> 144000 | E27: =E7*E17 -> 158400 | F27: =F7*F17 -> 174240 | G27: =G7*G17 -> 191664 | H27: =H7*H17 -> 210830.4 | I27: =I7*I17 -> 231913.44 | J27: =J7*J17 -> 255104.78 | K27: =K7*K17 -> 280615.26
A28: Plumber | D28: =D8*D18 -> 48000 | E28: =E8*E18 -> 50400 | F28: =F8*F18 -> 105840 | G28: =G8*G18 -> 111132 | H28: =H8*H18 -> 175032.9 | I28: =I8*I18 -> 183784.55 | J28: =J8*J18 -> 257298.36 | K28: =K8*K18 -> 270163.28
A29: Electrician | D29: =D9*D19 -> 48000 | E29: =E9*E19 -> 50400 | F29: =F9*F19 -> 105840 | G29: =G9*G19 -> 111132 | H29: =H9*H19 -> 175032.9 | I29: =I9*I19 -> 183784.55 | J29: =J9*J19 -> 257298.36 | K29: =K9*K19 -> 270163.28
A30: Admin | D30: =D10*D20 -> 48000 | E30: =E10*E20 -> 50400 | F30: =F10*F20 -> 52920 | G30: =G10*G20 -> 55566 | H30: =H10*H20 -> 58344.3 | I30: =I10*I20 -> 122523.03 | J30: =J10*J20 -> 128649.18 | K30: =K10*K20 -> 135081.64
A31: SUMMARY
A32: Annual Salary | D32: =SUM(D24:D30) -> 492000 | E32: =SUM(E24:E30) -> 534000 | F32: =SUM(F24:F30) -> 685680 | G32: =SUM(G24:G30) -> 741018 | H32: =SUM(H24:H30) -> 917916.9 | I32: =SUM(I24:I30) -> 1050549.6 | J32: =SUM(J24:J30) -> 1259749.1 | K32: =SUM(K24:K30) -> 1353561.8
A34: Office Desks
D35: Year 1 | E35: Year 2 | F35: Year 3 | G35: Year 4 | H35: Year 5 | I35: Year 6 | J35: Year 7 | K35: Year 8
A36: Desks needed | D36: =SUM(D4:D7,D10) -> 5 | E36: =SUM(E4:E7,E10) -> 5 | F36: =SUM(F4:F7,F10) -> 5 | G36: =SUM(G4:G7,G10) -> 5 | H36: =SUM(H4:H7,H10) -> 5 | I36: 6 | J36: 6 | K36: 6
A37: Annual rent per seat | D37: =Assumptions!B47*12 -> 24000 | E37: =D37*(1+Assumptions!$B$52) -> 25200 | F37: =E37*(1+Assumptions!$B$52) -> 26460 | G37: =F37*(1+Assumptions!$B$52) -> 27783 | H37: =G37*(1+Assumptions!$B$52) -> 29172.15 | I37: =H37*(1+Assumptions!$B$52) -> 30630.758 | J37: =I37*(1+Assumptions!$B$52) -> 32162.295 | K37: =J37*(1+Assumptions!$B$52) -> 33770.41
A38: Total rental cost | D38: =D37*D36 -> 120000 | E38: =E37*E36 -> 126000 | F38: =F37*F36 -> 132300 | G38: =G37*G36 -> 138915 | H38: =H37*H36 -> 145860.75 | I38: =I37*I36 -> 183784.55 | J38: =J37*J36 -> 192973.77 | K38: =K37*K36 -> 202622.46

Sheet CapEx & Storage
A1: CAPEX & STORAGE
E2: 0 | F2: =E2+1 -> 1 | G2: =F2+1 -> 2 | H2: =G2+1 -> 3 | I2: =H2+1 -> 4 | J2: =I2+1 -> 5 | K2: =J2+1 -> 6 | L2: =K2+1 -> 7
A3: SIMULATED ASSET REQUIREMENT
E4: Year 1 | F4: Year 2 | G4: Year 3 | H4: Year 4 | I4: Year 5 | J4: Year 6 | K4: Year 7 | L4: Year 8
A5: Cabins | E5: {=INDEX(Simulation!$D$2:$G$41,MATCH(1,(Simulation!$C$2:$C$41=$A5)*(Simulation!$A$2:$A$41=E$2+1),0),MATCH($D12,Simulation!$D$1:$G$1,0))} -> 80 | F5: {=INDEX(Simulation!$D$2:$G$41,MATCH(1,(Simulation!$C$2:$C$41=$A5)*(Simulation!$A$2:$A$41=F$2+1),0),MATCH($D12,Simulation!$D$1:$G$1,0))} -> 83 | G5: {=INDEX(Simulation!$D$2:$G$41,MATCH(1,(Simulation!$C$2:$C$41=$A5)*(Simulation!$A$2:$A$41=G$2+1),0),MATCH($D12,Simulation!$D$1:$G$1,0))} -> 90 | H5: {=INDEX(Simulation!$D$2:$G$41,MATCH(1,(Simulation!$C$2:$C$41=$A5)*(Simulation!$A$2:$A$41=H$2+1),0),MATCH($D12,Simulation!$D$1:$G$1,0))} -> 97 | I5: {=INDEX(Simulation!$D$2:$G$41,MATCH(1,(Simulation!$C$2:$C$41=$A5)*(Simulation!$A$2:$A$41=I$2+1),0),MATCH($D12,Simulation!$D$1:$G$1,0))} -> 100 | J5: {=INDEX(Simulation!$D$2:$G$41,MATCH(1,(Simulation!$C$2:$C$41=$A5)*(Simulation!$A$2:$A$41=J$2+1),0),MATCH($D12,Simulation!$D$1:$G$1,0))} -> 109 | K5: {=INDEX(Simulation!$D$2:$G$41,MATCH(1,(Simulation!$C$2:$C$41=$A5)*(Simulation!$A$2:$A$41=K$2+1),0),MATCH($D12,Simulation!$D$1:$G$1,0))} -> 120 | L5: {=INDEX(Simulation!$D$2:$G$41,MATCH(1,(Simulation!$C$2:$C$41=$A5)*(Simulation!$A$2:$A$41=L$2+1),0),MATCH($D12,Simulation!$D$1:$G$1,0))} -> 127
A6: Buggies | E6: {=INDEX(Simulation!$D$2:$G$41,MATCH(1,(Simulation!$C$2:$C$41=$A6)*(Simulation!$A$2:$A$41=E$2+1),0),MATCH($D13,Simulation!$D$1:$G$1,0))} -> 26 | F6: {=INDEX(Simulation!$D$2:$G$41,MATCH(1,(Simulation!$C$2:$C$41=$A6)*(Simulation!$A$2:$A$41=F$2+1),0),MATCH($D13,Simulation!$D$1:$G$1,0))} -> 28 | G6: {=INDEX(Simulation!$D$2:$G$41,MATCH(1,(Simulation!$C$2:$C$41=$A6)*(Simulation!$A$2:$A$41=G$2+1),0),MATCH($D13,Simulation!$D$1:$G$1,0))} -> 30 | H6: {=INDEX(Simulation!$D$2:$G$41,MATCH(1,(Simulation!$C$2:$C$41=$A6)*(Simulation!$A$2:$A$41=H$2+1),0),MATCH($D13,Simulation!$D$1:$G$1,0))} -> 34 | I6: {=INDEX(Simulation!$D$2:$G$41,MATCH(1,(Simulation!$C$2:$C$41=$A6)*(Simulation!$A$2:$A$41=I$2+1),0),MATCH($D13,Simulation!$D$1:$G$1,0))} -> 34 | J6: {=INDEX(Simulation!$D$2:$G$41,MATCH(1,(Simulation!$C$2:$C$41=$A6)*(Simulation!$A$2:$A$41=J$2+1),0),MATCH($D13,Simulation!$D$1:$G$1,0))} -> 38 | K6: {=INDEX(Simulation!$D$2:$G$41,MATCH(1,(Simulation!$C$2:$C$41=$A6)*(Simulation!$A$2:$A$41=K$2+1),0),MATCH($D13,Simulation!$D$1:$G$1,0))} -> 42 | L6: {=INDEX(Simulation!$D$2:$G$41,MATCH(1,(Simulation!$C$2:$C$41=$A6)*(Simulation!$A$2:$A$41=L$2+1),0),MATCH($D13,Simulation!$D$1:$G$1,0))} -> 46
A7: Barriers | E7: {=INDEX(Simulation!$D$2:$G$41,MATCH(1,(Simulation!$C$2:$C$41=$A7)*(Simulation!$A$2:$A$41=E$2+1),0),MATCH($D14,Simulation!$D$1:$G$1,0))} -> 2300 | F7: {=INDEX(Simulation!$D$2:$G$41,MATCH(1,(Simulation!$C$2:$C$41=$A7)*(Simulation!$A$2:$A$41=F$2+1),0),MATCH($D14,Simulation!$D$1:$G$1,0))} -> 2408 | G7: {=INDEX(Simulation!$D$2:$G$41,MATCH(1,(Simulation!$C$2:$C$41=$A7)*(Simulation!$A$2:$A$41=G$2+1),0),MATCH($D14,Simulation!$D$1:$G$1,0))} -> 2744 | H7: {=INDEX(Simulation!$D$2:$G$41,MATCH(1,(Simulation!$C$2:$C$41=$A7)*(Simulation!$A$2:$A$41=H$2+1),0),MATCH($D14,Simulation!$D$1:$G$1,0))} -> 2950 | I7: {=INDEX(Simulation!$D$2:$G$41,MATCH(1,(Simulation!$C$2:$C$41=$A7)*(Simulation!$A$2:$A$41=I$2+1),0),MATCH($D14,Simulation!$D$1:$G$1,0))} -> 3094 | J7: {=INDEX(Simulation!$D$2:$G$41,MATCH(1,(Simulation!$C$2:$C$41=$A7)*(Simulation!$A$2:$A$41=J$2+1),0),MATCH($D14,Simulation!$D$1:$G$1,0))} -> 3558 | K7: {=INDEX(Simulation!$D$2:$G$41,MATCH(1,(Simulation!$C$2:$C$41=$A7)*(Simulation!$A$2:$A$41=K$2+1),0),MATCH($D14,Simulation!$D$1:$G$1,0))} -> 3950 | L7: {=INDEX(Simulation!$D$2:$G$41,MATCH(1,(Simulation!$C$2:$C$41=$A7)*(Simulation!$A$2:$A$41=L$2+1),0),MATCH($D14,Simulation!$D$1:$G$1,0))} -> 4264
A8: Fencing | E8: {=INDEX(Simulation!$D$2:$G$41,MATCH(1,(Simulation!$C$2:$C$41=$A8)*(Simulation!$A$2:$A$41=E$2+1),0),MATCH($D15,Simulation!$D$1:$G$1,0))} -> 2960 | F8: {=INDEX(Simulation!$D$2:$G$41,MATCH(1,(Simulation!$C$2:$C$41=$A8)*(Simulation!$A$2:$A$41=F$2+1),0),MATCH($D15,Simulation!$D$1:$G$1,0))} -> 3010 | G8: {=INDEX(Simulation!$D$2:$G$41,MATCH(1,(Simulation!$C$2:$C$41=$A8)*(Simulation!$A$2:$A$41=G$2+1),0),MATCH($D15,Simulation!$D$1:$G$1,0))} -> 3230 | H8: {=INDEX(Simulation!$D$2:$G$41,MATCH(1,(Simulation!$C$2:$C$41=$A8)*(Simulation!$A$2:$A$41=H$2+1),0),MATCH($D15,Simulation!$D$1:$G$1,0))} -> 3440 | I8: {=INDEX(Simulation!$D$2:$G$41,MATCH(1,(Simulation!$C$2:$C$41=$A8)*(Simulation!$A$2:$A$41=I$2+1),0),MATCH($D15,Simulation!$D$1:$G$1,0))} -> 3590 | J8: {=INDEX(Simulation!$D$2:$G$41,MATCH(1,(Simulation!$C$2:$C$41=$A8)*(Simulation!$A$2:$A$41=J$2+1),0),MATCH($D15,Simulation!$D$1:$G$1,0))} -> 3880 | K8: {=INDEX(Simulation!$D$2:$G$41,MATCH(1,(Simulation!$C$2:$C$41=$A8)*(Simulation!$A$2:$A$41=K$2+1),0),MATCH($D15,Simulation!$D$1:$G$1,0))} -> 4340 | L8: {=INDEX(Simulation!$D$2:$G$41,MATCH(1,(Simulation!$C$2:$C$41=$A8)*(Simulation!$A$2:$A$41=L$2+1),0),MATCH($D15,Simulation!$D$1:$G$1,0))} -> 4490
A9: Flooring | E9: {=INDEX(Simulation!$D$2:$G$41,MATCH(1,(Simulation!$C$2:$C$41=$A9)*(Simulation!$A$2:$A$41=E$2+1),0),MATCH($D16,Simulation!$D$1:$G$1,0))} -> 740 | F9: {=INDEX(Simulation!$D$2:$G$41,MATCH(1,(Simulation!$C$2:$C$41=$A9)*(Simulation!$A$2:$A$41=F$2+1),0),MATCH($D16,Simulation!$D$1:$G$1,0))} -> 740 | G9: {=INDEX(Simulation!$D$2:$G$41,MATCH(1,(Simulation!$C$2:$C$41=$A9)*(Simulation!$A$2:$A$41=G$2+1),0),MATCH($D16,Simulation!$D$1:$G$1,0))} -> 840 | H9: {=INDEX(Simulation!$D$2:$G$41,MATCH(1,(Simulation!$C$2:$C$41=$A9)*(Simulation!$A$2:$A$41=H$2+1),0),MATCH($D16,Simulation!$D$1:$G$1,0))} -> 880 | I9: {=INDEX(Simulation!$D$2:$G$41,MATCH(1,(Simulation!$C$2:$C$41=$A9)*(Simulation!$A$2:$A$41=I$2+1),0),MATCH($D16,Simulation!$D$1:$G$1,0))} -> 918 | J9: {=INDEX(Simulation!$D$2:$G$41,MATCH(1,(Simulation!$C$2:$C$41=$A9)*(Simulation!$A$2:$A$41=J$2+1),0),MATCH($D16,Simulation!$D$1:$G$1,0))} -> 960 | K9: {=INDEX(Simulation!$D$2:$G$41,MATCH(1,(Simulation!$C$2:$C$41=$A9)*(Simulation!$A$2:$A$41=K$2+1),0),MATCH($D16,Simulation!$D$1:$G$1,0))} -> 1040 | L9: {=INDEX(Simulation!$D$2:$G$41,MATCH(1,(Simulation!$C$2:$C$41=$A9)*(Simulation!$A$2:$A$41=L$2+1),0),MATCH($D16,Simulation!$D$1:$G$1,0))} -> 1080
A10: ASSET PURCHASE: unit list & quantities by year
C11: Unit Price | D11: Coverage Pct. (Fleet Sizing) | E11: Year 1 | F11: Year 2 | G11: Year 3 | H11: Year 4 | I11: Year 5 | J11: Year 6 | K11: Year 7 | L11: Year 8 | M11: Cumulative Total Units | N11: Total CaPex
A12: Cabins | D12: 0.85 | E12: =E5 -> 80 | F12: =IF(F5>MAX($E$5:E5),F5-MAX($E$5:E5),0) -> 3 | G12: =IF(G5>MAX($E$5:F5),G5-MAX($E$5:F5),0) -> 7 | H12: =IF(H5>MAX($E$5:G5),H5-MAX($E$5:G5),0) -> 7 | I12: =IF(I5>MAX($E$5:H5),I5-MAX($E$5:H5),0) -> 3 | J12: =IF(J5>MAX($E$5:I5),J5-MAX($E$5:I5),0) -> 9 | K12: =IF(K5>MAX($E$5:J5),K5-MAX($E$5:J5),0) -> 11 | L12: =IF(L5>MAX($E$5:K5),L5-MAX($E$5:K5),0) -> 7 | M12: =SUM(E12:L12) -> 127 | N12: =SUM(E18:I18) -> 9971619
A13: Buggies | C13: =Assumptions!B29 -> 40000 | D13: =Assumptions!B11 -> 0.5 | E13: =E6 -> 26 | F13: =IF(F6>MAX($E$6:E6),F6-MAX($E$6:E6),0) -> 2 | G13: =IF(G6>MAX($E$6:F6),G6-MAX($E$6:F6),0) -> 2 | H13: =IF(H6>MAX($E$6:G6),H6-MAX($E$6:G6),0) -> 4 | I13: =IF(I6>MAX($E$6:H6),I6-MAX($E$6:H6),0) -> 0 | J13: =IF(J6>MAX($E$6:I6),J6-MAX($E$6:I6),0) -> 4 | K13: =IF(K6>MAX($E$6:J6),K6-MAX($E$6:J6),0) -> 4 | L13: =IF(L6>MAX($E$6:K6),L6-MAX($E$6:K6),0) -> 4 | M13: =SUM(E13:L13) -> 46 | N13: =SUM(E19:I19) -> 1374625.3
A14: Barriers | C14: =Assumptions!B33 -> 300 | D14: =Assumptions!B12 -> 0.85 | E14: =E7 -> 2300 | F14: =IF(F7>MAX($E$7:E7),F7-MAX($E$7:E7),0) -> 108 | G14: =IF(G7>MAX($E$7:F7),G7-MAX($E$7:F7),0) -> 336 | H14: =IF(H7>MAX($E$7:G7),H7-MAX($E$7:G7),0) -> 206 | I14: =IF(I7>MAX($E$7:H7),I7-MAX($E$7:H7),0) -> 144 | J14: =IF(J7>MAX($E$7:I7),J7-MAX($E$7:I7),0) -> 464 | K14: =IF(K7>MAX($E$7:J7),K7-MAX($E$7:J7),0) -> 392 | L14: =IF(L7>MAX($E$7:K7),L7-MAX($E$7:K7),0) -> 314 | M14: =SUM(E14:L14) -> 4264 | N14: =SUM(E20:I20) -> 940264.04
A15: Fencing | C15: =Assumptions!B34 -> 400 | D15: =Assumptions!B13 -> 0.85 | E15: =E8 -> 2960 | F15: =IF(F8>MAX($E$8:E8),F8-MAX($E$8:E8),0) -> 50 | G15: =IF(G8>MAX($E$8:F8),G8-MAX($E$8:F8),0) -> 220 | H15: =IF(H8>MAX($E$8:G8),H8-MAX($E$8:G8),0) -> 210 | I15: =IF(I8>MAX($E$8:H8),I8-MAX($E$8:H8),0) -> 150 | J15: =IF(J8>MAX($E$8:I8),J8-MAX($E$8:I8),0) -> 290 | K15: =IF(K8>MAX($E$8:J8),K8-MAX($E$8:J8),0) -> 460 | L15: =IF(L8>MAX($E$8:K8),L8-MAX($E$8:K8),0) -> 150 | M15: =SUM(E15:L15) -> 4490 | N15: =SUM(E21:I21) -> 1450042.6
A16: Flooring | C16: =Assumptions!B38 -> 500 | D16: =Assumptions!B14 -> 0.85 | E16: =E9 -> 740 | F16: =IF(F9>MAX($E$9:E9),F9-MAX($E$9:E9),0) -> 0 | G16: =IF(G9>MAX($E$9:F9),G9-MAX($E$9:F9),0) -> 100 | H16: =IF(H9>MAX($E$9:G9),H9-MAX($E$9:G9),0) -> 40 | I16: =IF(I9>MAX($E$9:H9),I9-MAX($E$9:H9),0) -> 38 | J16: =IF(J9>MAX($E$9:I9),J9-MAX($E$9:I9),0) -> 42 | K16: =IF(K9>MAX($E$9:J9),K9-MAX($E$9:J9),0) -> 80 | L16: =IF(L9>MAX($E$9:K9),L9-MAX($E$9:K9),0) -> 40 | M16: =SUM(E16:L16) -> 1080 | N16: =SUM(E22:I22) -> 463810.37
A17: SUMMARY
A18: Cabin CapEx | E18: =E48 -> 6658100 | F18: =F48 -> 764286 | G18: =G48 -> 708928.56 | H18: =H48 -> 884516.87 | I18: =I48 -> 955787.6 | J18: =J48 -> 0 | K18: =K48 -> 0 | L18: =L48 -> 0 | N18: =SUM(E18:I18) -> 9971619
A19: Buggies Yearly CapEx | E19: =E13*$C13*(1+Assumptions!$B$42)^'CapEx & Storage'!E$2 -> 1040000 | F19: =F13*$C13*(1+Assumptions!$B$42)^'CapEx & Storage'!F$2 -> 81600 | G19: =G13*$C13*(1+Assumptions!$B$42)^'CapEx & Storage'!G$2 -> 83232 | H19: =H13*$C13*(1+Assumptions!$B$42)^'CapEx & Storage'!H$2 -> 169793.28 | I19: =I13*$C13*(1+Assumptions!$B$42)^'CapEx & Storage'!I$2 -> 0 | J19: =J13*$C13*(1+Assumptions!$B$42)^'CapEx & Storage'!J$2 -> 176652.93 | K19: =K13*$C13*(1+Assumptions!$B$42)^'CapEx & Storage'!K$2 -> 180185.99 | L19: =L13*$C13*(1+Assumptions!$B$42)^'CapEx & Storage'!L$2 -> 183789.71 | N19: =SUM(E19:I19) -> 1374625.3
A20: Barriers CapEx | E20: =E14*$C14*(1+Assumptions!$B$42)^'CapEx & Storage'!E$2 -> 690000 | F20: =F14*$C14*(1+Assumptions!$B$42)^'CapEx & Storage'!F$2 -> 33048 | G20: =G14*$C14*(1+Assumptions!$B$42)^'CapEx & Storage'!G$2 -> 104872.32 | H20: =H14*$C14*(1+Assumptions!$B$42)^'CapEx & Storage'!H$2 -> 65582.654 | I20: =I14*$C14*(1+Assumptions!$B$42)^'CapEx & Storage'!I$2 -> 46761.069 | J20: =J14*$C14*(1+Assumptions!$B$42)^'CapEx & Storage'!J$2 -> 153688.05 | K20: =K14*$C14*(1+Assumptions!$B$42)^'CapEx & Storage'!K$2 -> 132436.7 | L20: =L14*$C14*(1+Assumptions!$B$42)^'CapEx & Storage'!L$2 -> 108206.19 | N20: =SUM(E20:I20) -> 940264.04
A21: Fencing CapEx | E21: =E15*$C15*(1+Assumptions!$B$42)^'CapEx & Storage'!E$2 -> 1184000 | F21: =F15*$C15*(1+Assumptions!$B$42)^'CapEx & Storage'!F$2 -> 20400 | G21: =G15*$C15*(1+Assumptions!$B$42)^'CapEx & Storage'!G$2 -> 91555.2 | H21: =H15*$C15*(1+Assumptions!$B$42)^'CapEx & Storage'!H$2 -> 89141.472 | I21: =I15*$C15*(1+Assumptions!$B$42)^'CapEx & Storage'!I$2 -> 64945.93 | J21: =J15*$C15*(1+Assumptions!$B$42)^'CapEx & Storage'!J$2 -> 128073.37 | K21: =K15*$C15*(1+Assumptions!$B$42)^'CapEx & Storage'!K$2 -> 207213.89 | L21: =L15*$C15*(1+Assumptions!$B$42)^'CapEx & Storage'!L$2 -> 68921.14 | N21: =SUM(E21:I21) -> 1450042.6
A22: Terratrak CapEx | E22: =E16*$C16*(1+Assumptions!$B$42)^'CapEx & Storage'!E$2 -> 370000 | F22: =F16*$C16*(1+Assumptions!$B$42)^'CapEx & Storage'!F$2 -> 0 | G22: =G16*$C16*(1+Assumptions!$B$42)^'CapEx & Storage'!G$2 -> 52020 | H22: =H16*$C16*(1+Assumptions!$B$42)^'CapEx & Storage'!H$2 -> 21224.16 | I22: =I16*$C16*(1+Assumptions!$B$42)^'CapEx & Storage'!I$2 -> 20566.211 | J22: =J16*$C16*(1+Assumptions!$B$42)^'CapEx & Storage'!J$2 -> 23185.697 | K22: =K16*$C16*(1+Assumptions!$B$42)^'CapEx & Storage'!K$2 -> 45046.497 | L22: =L16*$C16*(1+Assumptions!$B$42)^'CapEx & Storage'!L$2 -> 22973.713 | N22: =SUM(E22:I22) -> 463810.37
N23: =SUM(N18:N22) -> 14200361
A25: CABINS: unit list, quantities by year, and storage footprint
A26: Cabin Type | B26: Description | C26: Unit Price (AED) | D26: Floor Area (sqm) | E26: Year 1 | F26: Year 2 | G26: Year 3 | H26: Year 4 | I26: Year 5 | J26: Year 6 | K26: Year 7 | L26: Year 8 | M26: Cumulative Total Units | N26: Total CapEx
A27: 20 Ft Office | B27: Open Layout (1 Door) | C27: 26500 | D27: 15 | E27: 4 | F27: 1 | H27: 1 | M27: =SUM(E27:L27) -> 6 | N27: =IFERROR(E27*C27,0)+IFERROR(F27*C27*(1+Assumptions!$B$42)^1,0)+IFERROR(G27*C27*(1+Assumptions!$B$42)^2,0)+IFERROR(H27*C27*(1+Assumptions!$B$42)^3,0)+IFERROR(I27*C27*(1+Assumptions!$B$42)^4,0) -> 161152.01
A28: 20 Ft Office | B28: Open Layout (2 Doors) | C28: 28400 | D28: 15 | E28: 3 | F28: 1 | H28: 1 | I28: 1 | M28: =SUM(E28:L28) -> 6 | N28: =IFERROR(E28*C28,0)+IFERROR(F28*C28*(1+Assumptions!$B$42)^1,0)+IFERROR(G28*C28*(1+Assumptions!$B$42)^2,0)+IFERROR(H28*C28*(1+Assumptions!$B$42)^3,0)+IFERROR(I28*C28*(1+Assumptions!$B$42)^4,0) -> 175047.38
A29: 40 Ft Office | B29: Open Layout (2 Windows) | C29: 46200 | D29: 37 | E29: 5 | H29: 1 | I29: 2 | M29: =SUM(E29:L29) -> 8 | N29: =IFERROR(E29*C29,0)+IFERROR(F29*C29*(1+Assumptions!$B$42)^1,0)+IFERROR(G29*C29*(1+Assumptions!$B$42)^2,0)+IFERROR(H29*C29*(1+Assumptions!$B$42)^3,0)+IFERROR(I29*C29*(1+Assumptions!$B$42)^4,0) -> 380044.54
A30: 40 Ft Office | B30: Open Layout (Multi-window) | C30: 49700 | D30: 37 | E30: 6 | G30: 1 | H30: 1 | M30: =SUM(E30:L30) -> 8 | N30: =IFERROR(E30*C30,0)+IFERROR(F30*C30*(1+Assumptions!$B$42)^1,0)+IFERROR(G30*C30*(1+Assumptions!$B$42)^2,0)+IFERROR(H30*C30*(1+Assumptions!$B$42)^3,0)+IFERROR(I30*C30*(1+Assumptions!$B$42)^4,0) -> 402649.92
A31: 40 Ft Split | B31: 2 Offices | C31: 52700 | D31: 37 | E31: 5 | G31: 1 | H31: 1 | I31: 2 | M31: =SUM(E31:L31) -> 9 | N31: =IFERROR(E31*C31,0)+IFERROR(F31*C31*(1+Assumptions!$B$42)^1,0)+IFERROR(G31*C31*(1+Assumptions!$B$42)^2,0)+IFERROR(H31*C31*(1+Assumptions!$B$42)^3,0)+IFERROR(I31*C31*(1+Assumptions!$B$42)^4,0) -> 488343.09
A32: 40 Ft Split | B32: 2 Offices + Toilet + Pantry | C32: 109300 | D32: 37 | E32: 5 | H32: 1 | I32: 1 | M32: =SUM(E32:L32) -> 7 | N32: =IFERROR(E32*C32,0)+IFERROR(F32*C32*(1+Assumptions!$B$42)^1,0)+IFERROR(G32*C32*(1+Assumptions!$B$42)^2,0)+IFERROR(H32*C32*(1+Assumptions!$B$42)^3,0)+IFERROR(I32*C32*(1+Assumptions!$B$42)^4,0) -> 780799.87
A33: 20 Ft Ticketing | B33: Counter + 5 Windows | C33: 28700 | D33: 15 | E33: 4 | G33: 1 | M33: =SUM(E33:L33) -> 5 | N33: =IFERROR(E33*C33,0)+IFERROR(F33*C33*(1+Assumptions!$B$42)^1,0)+IFERROR(G33*C33*(1+Assumptions!$B$42)^2,0)+IFERROR(H33*C33*(1+Assumptions!$B$42)^3,0)+IFERROR(I33*C33*(1+Assumptions!$B$42)^4,0) -> 144659.48
A34: 40 Ft Ticketing | B34: Counter + 9 Windows | C34: 56400 | D34: 49 | E34: 4 | G34: 1 | M34: =SUM(E34:L34) -> 5 | N34: =IFERROR(E34*C34,0)+IFERROR(F34*C34*(1+Assumptions!$B$42)^1,0)+IFERROR(G34*C34*(1+Assumptions!$B$42)^2,0)+IFERROR(H34*C34*(1+Assumptions!$B$42)^3,0)+IFERROR(I34*C34*(1+Assumptions!$B$42)^4,0) -> 284278.56
A35: 40 Ft Toilet (Male) | B35: With Urinals + Baseframe + Stairs + Tanks | C35: 153900 | D35: 49 | E35: 5 | F35: 1 | M35: =SUM(E35:L35) -> 6 | N35: =IFERROR(E35*C35,0)+IFERROR(F35*C35*(1+Assumptions!$B$42)^1,0)+IFERROR(G35*C35*(1+Assumptions!$B$42)^2,0)+IFERROR(H35*C35*(1+Assumptions!$B$42)^3,0)+IFERROR(I35*C35*(1+Assumptions!$B$42)^4,0) -> 926478
A36: 40 Ft Toilet (Female) | B36: Baseframe + Stairs + Tanks | C36: 164100 | D36: 49 | E36: 5 | F36: 1 | M36: =SUM(E36:L36) -> 6 | N36: =IFERROR(E36*C36,0)+IFERROR(F36*C36*(1+Assumptions!$B$42)^1,0)+IFERROR(G36*C36*(1+Assumptions!$B$42)^2,0)+IFERROR(H36*C36*(1+Assumptions!$B$42)^3,0)+IFERROR(I36*C36*(1+Assumptions!$B$42)^4,0) -> 987882
A37: 40 Ft Toilet (Split) | B37: Half Male / Half Female + Baseframe + Stairs + Tanks | C37: 160000 | D37: 49 | E37: 5 | F37: 1 | G37: 2 | M37: =SUM(E37:L37) -> 8 | N37: =IFERROR(E37*C37,0)+IFERROR(F37*C37*(1+Assumptions!$B$42)^1,0)+IFERROR(G37*C37*(1+Assumptions!$B$42)^2,0)+IFERROR(H37*C37*(1+Assumptions!$B$42)^3,0)+IFERROR(I37*C37*(1+Assumptions!$B$42)^4,0) -> 1296128
A38: 20 Ft Toilet (Male) | B38: With Urinals + Baseframe + Stairs + Tanks | C38: 90100 | D38: 24 | E38: 5 | G38: 1 | M38: =SUM(E38:L38) -> 6 | N38: =IFERROR(E38*C38,0)+IFERROR(F38*C38*(1+Assumptions!$B$42)^1,0)+IFERROR(G38*C38*(1+Assumptions!$B$42)^2,0)+IFERROR(H38*C38*(1+Assumptions!$B$42)^3,0)+IFERROR(I38*C38*(1+Assumptions!$B$42)^4,0) -> 544240.04
A39: 20 Ft Toilet (Female) | B39: Baseframe + Stairs + Tanks | C39: 83800 | D39: 18 | E39: 5 | G39: 1 | M39: =SUM(E39:L39) -> 6 | N39: =IFERROR(E39*C39,0)+IFERROR(F39*C39*(1+Assumptions!$B$42)^1,0)+IFERROR(G39*C39*(1+Assumptions!$B$42)^2,0)+IFERROR(H39*C39*(1+Assumptions!$B$42)^3,0)+IFERROR(I39*C39*(1+Assumptions!$B$42)^4,0) -> 506185.52
A40: 20 Ft Shower Unit | B40: With Showers + Baseframe + Stairs + Tanks | C40: 82600 | D40: 18 | E40: 2 | H40: 1 | I40: 1 | M40: =SUM(E40:L40) -> 4 | N40: =IFERROR(E40*C40,0)+IFERROR(F40*C40*(1+Assumptions!$B$42)^1,0)+IFERROR(G40*C40*(1+Assumptions!$B$42)^2,0)+IFERROR(H40*C40*(1+Assumptions!$B$42)^3,0)+IFERROR(I40*C40*(1+Assumptions!$B$42)^4,0) -> 342264.68
A41: 8 Ft POD | B41: POD & Baby Changing | C41: 26800 | D41: 7 | E41: 4 | F41: 1 | I41: 1 | M41: =SUM(E41:L41) -> 6 | N41: =IFERROR(E41*C41,0)+IFERROR(F41*C41*(1+Assumptions!$B$42)^1,0)+IFERROR(G41*C41*(1+Assumptions!$B$42)^2,0)+IFERROR(H41*C41*(1+Assumptions!$B$42)^3,0)+IFERROR(I41*C41*(1+Assumptions!$B$42)^4,0) -> 163545.18
...

Sheet FY1 Event & Demand Timeline
A1: EVENT UTILISATION TIMELINE │ green = Mobilisation, red = Live event, blue = Demobilisation
D2: Year | E2: 2026 | CS2: 2027
D3: Month | E3: Oct | AJ3: Nov | BN3: Dec | CS3: Jan | DX3: Feb | EZ3: Mar | GE3: Apr
D4: Day | E4: 1 | F4: 2 | G4: 3 | H4: 4 | I4: 5 | J4: 6 | K4: 7 | L4: 8 | M4: 9 | N4: 10 | O4: 11 | P4: 12 | Q4: 13 | R4: 14 | S4: 15 | T4: 16 | U4: 17 | V4: 18 | W4: 19 | X4: 20 | Y4: 21 | Z4: 22 | AA4: 23 | AB4: 24 | AC4: 25 | AD4: 26 | AE4: 27 | AF4: 28 | AG4: 29 | AH4: 30 | AI4: 31 | AJ4: 1 | AK4: 2 | AL4: 3 | AM4: 4 | AN4: 5 | AO4: 6 | AP4: 7 | AQ4: 8 | AR4: 9 | AS4: 10 | AT4: 11 | AU4: 12 | AV4: 13 | AW4: 14 | AX4: 15 | AY4: 16 | AZ4: 17 | BA4: 18 | BB4: 19 | BC4: 20 | BD4: 21 | BE4: 22 | BF4: 23 | BG4: 24 | BH4: 25 | BI4: 26 | BJ4: 27 | BK4: 28 | BL4: 29 | BM4: 30 | BN4: 1 | BO4: 2 | BP4: 3 | BQ4: 4 | BR4: 5 | BS4: 6 | BT4: 7 | BU4: 8 | BV4: 9 | BW4: 10 | BX4: 11 | BY4: 12 | BZ4: 13 | CA4: 14 | CB4: 15 | CC4: 16 | CD4: 17 | CE4: 18 | CF4: 19 | CG4: 20 | CH4: 21 | CI4: 22 | CJ4: 23 | CK4: 24 | CL4: 25 | CM4: 26 | CN4: 27 | CO4: 28 | CP4: 29 | CQ4: 30 | CR4: 31 | CS4: 1 | CT4: 2 | CU4: 3 | CV4: 4 | CW4: 5 | CX4: 6 | CY4: 7 | CZ4: 8 | DA4: 9 | DB4: 10 | DC4: 11 | DD4: 12 | DE4: 13 | DF4: 14 | DG4: 15 | DH4: 16 | DI4: 17 | DJ4: 18 | DK4: 19 | DL4: 20 | DM4: 21 | DN4: 22 | DO4: 23 | DP4: 24 | DQ4: 25 | DR4: 26 | DS4: 27 | DT4: 28 | DU4: 29 | DV4: 30 | DW4: 31 | DX4: 1 | DY4: 2 | DZ4: 3 | EA4: 4 | EB4: 5 | EC4: 6 | ED4: 7 | EE4: 8 | EF4: 9 | EG4: 10 | EH4: 11 | EI4: 12 | EJ4: 13 | EK4: 14 | EL4: 15 | EM4: 16 | EN4: 17 | EO4: 18 | EP4: 19 | EQ4: 20 | ER4: 21 | ES4: 22 | ET4: 23 | EU4: 24 | EV4: 25 | EW4: 26 | EX4: 27 | EY4: 28 | EZ4: 1 | FA4: 2 | FB4: 3 | FC4: 4 | FD4: 5 | FE4: 6 | FF4: 7 | FG4: 8 | FH4: 9 | FI4: 10 | FJ4: 11 | FK4: 12 | FL4: 13 | FM4: 14 | FN4: 15 | FO4: 16 | FP4: 17 | FQ4: 18 | FR4: 19 | FS4: 20 | FT4: 21 | FU4: 22 | FV4: 23 | FW4: 24 | FX4: 25 | FY4: 26 | FZ4: 27 | GA4: 28 | GB4: 29 | GC4: 30 | GD4: 31 | GE4: 1 | GF4: 2 | GG4: 3 | GH4: 4 | GI4: 5 | GJ4: 6 | GK4: 7 | GL4: 8 | GM4: 9 | GN4: 10 | GO4: 11 | GP4: 12 | GQ4: 13 | GR4: 14 | GS4: 15 | GT4: 16 | GU4: 17 | GV4: 18 | GW4: 19 | GX4: 20 | GY4: 21 | GZ4: 22 | HA4: 23 | HB4: 24 | HC4: 25 | HD4: 26 | HE4: 27 | HF4: 28 | HG4: 29 | HH4: 30
D5: Date | E5: =DATE(2026,10,1) -> 46296 | F5: =E5+1 -> 46297 | G5: =F5+1 -> 46298 | H5: =G5+1 -> 46299 | I5: =H5+1 -> 46300 | J5: =I5+1 -> 46301 | K5: =J5+1 -> 46302 | L5: =K5+1 -> 46303 | M5: =L5+1 -> 46304 | ... HH5: =HG5+1 -> 46507
A6: CABINS | B6: Start | C6: End | D6: Count
A7: ='FY1 Event Pipeline'!A4 -> Saadiyat Nights | B7: =_xlfn.XLOOKUP(A7,'FY1 Event Pipeline'!$A$4:$A$15,'FY1 Event Pipeline'!$H$4:$H$15) -> 46297 | C7: =_xlfn.XLOOKUP(A7,'FY1 Event Pipeline'!$A$4:$A$15,'FY1 Event Pipeline'!$J$4:$J$15) -> 46453 | D7: =_xlfn.XLOOKUP(A7,'FY1 Event Pipeline'!$A$4:$A$15,'FY1 Event Pipeline'!$N$4:$N$15) -> 10 | E7: =IF(AND(E$5>=$B7,E$5<=$C7),$D7,"") | F7: =IF(AND(F$5>=$B7,F$5<=$C7),$D7,"") -> 10 | G7: =IF(AND(G$5>=$B7,G$5<=$C7),$D7,"") -> 10 | H7: =IF(AND(H$5>=$B7,H$5<=$C7),$D7,"") -> 10 | I7: =IF(AND(I$5>=$B7,I$5<=$C7),$D7,"") -> 10 | J7: =IF(AND(J$5>=$B7,J$5<=$C7),$D7,"") -> 10 | K7: =IF(AND(K$5>=$B7,K$5<=$C7),$D7,"") -> 10 | L7: =IF(AND(L$5>=$B7,L$5<=$C7),$D7,"") -> 10 | ... HH7: =IF(AND(HH$5>=$B7,HH$5<=$C7),$D7,"")
A8: ='FY1 Event Pipeline'!A5 -> BRED X | B8: =_xlfn.XLOOKUP(A8,'FY1 Event Pipeline'!$A$4:$A$15,'FY1 Event Pipeline'!$H$4:$H$15) -> 46318 | C8: =_xlfn.XLOOKUP(A8,'FY1 Event Pipeline'!$A$4:$A$15,'FY1 Event Pipeline'!$J$4:$J$15) -> 46339 | D8: =_xlfn.XLOOKUP(A8,'FY1 Event Pipeline'!$A$4:$A$15,'FY1 Event Pipeline'!$N$4:$N$15) -> 8 | E8: =IF(AND(E$5>=$B8,E$5<=$C8),$D8,"") | F8: =IF(AND(F$5>=$B8,F$5<=$C8),$D8,"") | G8: =IF(AND(G$5>=$B8,G$5<=$C8),$D8,"") | H8: =IF(AND(H$5>=$B8,H$5<=$C8),$D8,"") | I8: =IF(AND(I$5>=$B8,I$5<=$C8),$D8,"") | J8: =IF(AND(J$5>=$B8,J$5<=$C8),$D8,"") | K8: =IF(AND(K$5>=$B8,K$5<=$C8),$D8,"") | L8: =IF(AND(L$5>=$B8,L$5<=$C8),$D8,"") | ... HH8: =IF(AND(HH$5>=$B8,HH$5<=$C8),$D8,"")
A9: ='FY1 Event Pipeline'!A6 -> MOTN DHA | B9: =_xlfn.XLOOKUP(A9,'FY1 Event Pipeline'!$A$4:$A$15,'FY1 Event Pipeline'!$H$4:$H$15) -> 46330 | C9: =_xlfn.XLOOKUP(A9,'FY1 Event Pipeline'!$A$4:$A$15,'FY1 Event Pipeline'!$J$4:$J$15) -> 46352 | D9: =_xlfn.XLOOKUP(A9,'FY1 Event Pipeline'!$A$4:$A$15,'FY1 Event Pipeline'!$N$4:$N$15) -> 8 | E9: =IF(AND(E$5>=$B9,E$5<=$C9),$D9,"") | F9: =IF(AND(F$5>=$B9,F$5<=$C9),$D9,"") | G9: =IF(AND(G$5>=$B9,G$5<=$C9),$D9,"") | H9: =IF(AND(H$5>=$B9,H$5<=$C9),$D9,"") | I9: =IF(AND(I$5>=$B9,I$5<=$C9),$D9,"") | J9: =IF(AND(J$5>=$B9,J$5<=$C9),$D9,"") | K9: =IF(AND(K$5>=$B9,K$5<=$C9),$D9,"") | L9: =IF(AND(L$5>=$B9,L$5<=$C9),$D9,"") | ... HH9: =IF(AND(HH$5>=$B9,HH$5<=$C9),$D9,"")
A10: ='FY1 Event Pipeline'!A7 -> No Art UAE | B10: =_xlfn.XLOOKUP(A10,'FY1 Event Pipeline'!$A$4:$A$15,'FY1 Event Pipeline'!$H$4:$H$15) -> 46332 | C10: =_xlfn.XLOOKUP(A10,'FY1 Event Pipeline'!$A$4:$A$15,'FY1 Event Pipeline'!$J$4:$J$15) -> 46353 | D10: =_xlfn.XLOOKUP(A10,'FY1 Event Pipeline'!$A$4:$A$15,'FY1 Event Pipeline'!$N$4:$N$15) -> 24 | E10: =IF(AND(E$5>=$B10,E$5<=$C10),$D10,"") | F10: =IF(AND(F$5>=$B10,F$5<=$C10),$D10,"") | G10: =IF(AND(G$5>=$B10,G$5<=$C10),$D10,"") | H10: =IF(AND(H$5>=$B10,H$5<=$C10),$D10,"") | I10: =IF(AND(I$5>=$B10,I$5<=$C10),$D10,"") | J10: =IF(AND(J$5>=$B10,J$5<=$C10),$D10,"") | K10: =IF(AND(K$5>=$B10,K$5<=$C10),$D10,"") | L10: =IF(AND(L$5>=$B10,L$5<=$C10),$D10,"") | ... HH10: =IF(AND(HH$5>=$B10,HH$5<=$C10),$D10,"")
A11: ='FY1 Event Pipeline'!A8 -> Tanweer Festival | B11: =_xlfn.XLOOKUP(A11,'FY1 Event Pipeline'!$A$4:$A$15,'FY1 Event Pipeline'!$H$4:$H$15) -> 46340 | C11: =_xlfn.XLOOKUP(A11,'FY1 Event Pipeline'!$A$4:$A$15,'FY1 Event Pipeline'!$J$4:$J$15) -> 46352 | D11: =_xlfn.XLOOKUP(A11,'FY1 Event Pipeline'!$A$4:$A$15,'FY1 Event Pipeline'!$N$4:$N$15) -> 0 | E11: =IF(AND(E$5>=$B11,E$5<=$C11),$D11,"") | F11: =IF(AND(F$5>=$B11,F$5<=$C11),$D11,"") | G11: =IF(AND(G$5>=$B11,G$5<=$C11),$D11,"") | H11: =IF(AND(H$5>=$B11,H$5<=$C11),$D11,"") | I11: =IF(AND(I$5>=$B11,I$5<=$C11),$D11,"") | J11: =IF(AND(J$5>=$B11,J$5<=$C11),$D11,"") | K11: =IF(AND(K$5>=$B11,K$5<=$C11),$D11,"") | L11: =IF(AND(L$5>=$B11,L$5<=$C11),$D11,"") | ... HH11: =IF(AND(HH$5>=$B11,HH$5<=$C11),$D11,"")
A12: ='FY1 Event Pipeline'!A9 -> MOTN AAN | B12: =_xlfn.XLOOKUP(A12,'FY1 Event Pipeline'!$A$4:$A$15,'FY1 Event Pipeline'!$H$4:$H$15) -> 46336 | C12: =_xlfn.XLOOKUP(A12,'FY1 Event Pipeline'!$A$4:$A$15,'FY1 Event Pipeline'!$J$4:$J$15) -> 46362 | D12: =_xlfn.XLOOKUP(A12,'FY1 Event Pipeline'!$A$4:$A$15,'FY1 Event Pipeline'!$N$4:$N$15) -> 18 | E12: =IF(AND(E$5>=$B12,E$5<=$C12),$D12,"") | F12: =IF(AND(F$5>=$B12,F$5<=$C12),$D12,"") | G12: =IF(AND(G$5>=$B12,G$5<=$C12),$D12,"") | H12: =IF(AND(H$5>=$B12,H$5<=$C12),$D12,"") | I12: =IF(AND(I$5>=$B12,I$5<=$C12),$D12,"") | J12: =IF(AND(J$5>=$B12,J$5<=$C12),$D12,"") | K12: =IF(AND(K$5>=$B12,K$5<=$C12),$D12,"") | L12: =IF(AND(L$5>=$B12,L$5<=$C12),$D12,"") | ... HH12: =IF(AND(HH$5>=$B12,HH$5<=$C12),$D12,"")
A13: ='FY1 Event Pipeline'!A10 -> F1 Afterparty | B13: =_xlfn.XLOOKUP(A13,'FY1 Event Pipeline'!$A$4:$A$15,'FY1 Event Pipeline'!$H$4:$H$15) -> 46353 | C13: =_xlfn.XLOOKUP(A13,'FY1 Event Pipeline'!$A$4:$A$15,'FY1 Event Pipeline'!$J$4:$J$15) -> 46365 | D13: =_xlfn.XLOOKUP(A13,'FY1 Event Pipeline'!$A$4:$A$15,'FY1 Event Pipeline'!$N$4:$N$15) -> 29 | E13: =IF(AND(E$5>=$B13,E$5<=$C13),$D13,"") | F13: =IF(AND(F$5>=$B13,F$5<=$C13),$D13,"") | G13: =IF(AND(G$5>=$B13,G$5<=$C13),$D13,"") | H13: =IF(AND(H$5>=$B13,H$5<=$C13),$D13,"") | I13: =IF(AND(I$5>=$B13,I$5<=$C13),$D13,"") | J13: =IF(AND(J$5>=$B13,J$5<=$C13),$D13,"") | K13: =IF(AND(K$5>=$B13,K$5<=$C13),$D13,"") | L13: =IF(AND(L$5>=$B13,L$5<=$C13),$D13,"") | ... HH13: =IF(AND(HH$5>=$B13,HH$5<=$C13),$D13,"")
A14: ='FY1 Event Pipeline'!A11 -> MOTN AUH | B14: =_xlfn.XLOOKUP(A14,'FY1 Event Pipeline'!$A$4:$A$15,'FY1 Event Pipeline'!$H$4:$H$15) -> 46346 | C14: =_xlfn.XLOOKUP(A14,'FY1 Event Pipeline'!$A$4:$A$15,'FY1 Event Pipeline'!$J$4:$J$15) -> 46398 | D14: =_xlfn.XLOOKUP(A14,'FY1 Event Pipeline'!$A$4:$A$15,'FY1 Event Pipeline'!$N$4:$N$15) -> 20 | E14: =IF(AND(E$5>=$B14,E$5<=$C14),$D14,"") | F14: =IF(AND(F$5>=$B14,F$5<=$C14),$D14,"") | G14: =IF(AND(G$5>=$B14,G$5<=$C14),$D14,"") | H14: =IF(AND(H$5>=$B14,H$5<=$C14),$D14,"") | I14: =IF(AND(I$5>=$B14,I$5<=$C14),$D14,"") | J14: =IF(AND(J$5>=$B14,J$5<=$C14),$D14,"") | K14: =IF(AND(K$5>=$B14,K$5<=$C14),$D14,"") | L14: =IF(AND(L$5>=$B14,L$5<=$C14),$D14,"") | ... HH14: =IF(AND(HH$5>=$B14,HH$5<=$C14),$D14,"")
A15: ='FY1 Event Pipeline'!A12 -> Yas Winterfest | B15: =_xlfn.XLOOKUP(A15,'FY1 Event Pipeline'!$A$4:$A$15,'FY1 Event Pipeline'!$H$4:$H$15) -> 46352 | C15: =_xlfn.XLOOKUP(A15,'FY1 Event Pipeline'!$A$4:$A$15,'FY1 Event Pipeline'!$J$4:$J$15) -> 46384 | D15: =_xlfn.XLOOKUP(A15,'FY1 Event Pipeline'!$A$4:$A$15,'FY1 Event Pipeline'!$N$4:$N$15) -> 6 | E15: =IF(AND(E$5>=$B15,E$5<=$C15),$D15,"") | F15: =IF(AND(F$5>=$B15,F$5<=$C15),$D15,"") | G15: =IF(AND(G$5>=$B15,G$5<=$C15),$D15,"") | H15: =IF(AND(H$5>=$B15,H$5<=$C15),$D15,"") | I15: =IF(AND(I$5>=$B15,I$5<=$C15),$D15,"") | J15: =IF(AND(J$5>=$B15,J$5<=$C15),$D15,"") | K15: =IF(AND(K$5>=$B15,K$5<=$C15),$D15,"") | L15: =IF(AND(L$5>=$B15,L$5<=$C15),$D15,"") | ... HH15: =IF(AND(HH$5>=$B15,HH$5<=$C15),$D15,"")
A16: ='FY1 Event Pipeline'!A13 -> Animenia | B16: =_xlfn.XLOOKUP(A16,'FY1 Event Pipeline'!$A$4:$A$15,'FY1 Event Pipeline'!$H$4:$H$15) -> 46414 | C16: =_xlfn.XLOOKUP(A16,'FY1 Event Pipeline'!$A$4:$A$15,'FY1 Event Pipeline'!$J$4:$J$15) -> 46436 | D16: =_xlfn.XLOOKUP(A16,'FY1 Event Pipeline'!$A$4:$A$15,'FY1 Event Pipeline'!$N$4:$N$15) -> 8 | E16: =IF(AND(E$5>=$B16,E$5<=$C16),$D16,"") | F16: =IF(AND(F$5>=$B16,F$5<=$C16),$D16,"") | G16: =IF(AND(G$5>=$B16,G$5<=$C16),$D16,"") | H16: =IF(AND(H$5>=$B16,H$5<=$C16),$D16,"") | I16: =IF(AND(I$5>=$B16,I$5<=$C16),$D16,"") | J16: =IF(AND(J$5>=$B16,J$5<=$C16),$D16,"") | K16: =IF(AND(K$5>=$B16,K$5<=$C16),$D16,"") | L16: =IF(AND(L$5>=$B16,L$5<=$C16),$D16,"") | ... HH16: =IF(AND(HH$5>=$B16,HH$5<=$C16),$D16,"")
A17: ='FY1 Event Pipeline'!A14 -> DAZ | B17: =_xlfn.XLOOKUP(A17,'FY1 Event Pipeline'!$A$4:$A$15,'FY1 Event Pipeline'!$H$4:$H$15) -> 46466 | C17: =_xlfn.XLOOKUP(A17,'FY1 Event Pipeline'!$A$4:$A$15,'FY1 Event Pipeline'!$J$4:$J$15) -> 46496 | D17: =_xlfn.XLOOKUP(A17,'FY1 Event Pipeline'!$A$4:$A$15,'FY1 Event Pipeline'!$N$4:$N$15) -> 15 | E17: =IF(AND(E$5>=$B17,E$5<=$C17),$D17,"") | F17: =IF(AND(F$5>=$B17,F$5<=$C17),$D17,"") | G17: =IF(AND(G$5>=$B17,G$5<=$C17),$D17,"") | H17: =IF(AND(H$5>=$B17,H$5<=$C17),$D17,"") | I17: =IF(AND(I$5>=$B17,I$5<=$C17),$D17,"") | J17: =IF(AND(J$5>=$B17,J$5<=$C17),$D17,"") | K17: =IF(AND(K$5>=$B17,K$5<=$C17),$D17,"") | L17: =IF(AND(L$5>=$B17,L$5<=$C17),$D17,"") | ... HH17: =IF(AND(HH$5>=$B17,HH$5<=$C17),$D17,"")
A18: ='FY1 Event Pipeline'!A15 -> BRED | B18: =_xlfn.XLOOKUP(A18,'FY1 Event Pipeline'!$A$4:$A$15,'FY1 Event Pipeline'!$H$4:$H$15) -> 46492 | C18: =_xlfn.XLOOKUP(A18,'FY1 Event Pipeline'!$A$4:$A$15,'FY1 Event Pipeline'!$J$4:$J$15) -> 46506 | D18: =_xlfn.XLOOKUP(A18,'FY1 Event Pipeline'!$A$4:$A$15,'FY1 Event Pipeline'!$N$4:$N$15) -> 22 | E18: =IF(AND(E$5>=$B18,E$5<=$C18),$D18,"") | F18: =IF(AND(F$5>=$B18,F$5<=$C18),$D18,"") | G18: =IF(AND(G$5>=$B18,G$5<=$C18),$D18,"") | H18: =IF(AND(H$5>=$B18,H$5<=$C18),$D18,"") | I18: =IF(AND(I$5>=$B18,I$5<=$C18),$D18,"") | J18: =IF(AND(J$5>=$B18,J$5<=$C18),$D18,"") | K18: =IF(AND(K$5>=$B18,K$5<=$C18),$D18,"") | L18: =IF(AND(L$5>=$B18,L$5<=$C18),$D18,"") | ... HH18: =IF(AND(HH$5>=$B18,HH$5<=$C18),$D18,"")
A19: MAX CABINS ON-HIRE | D19: =MAX(F19:HH19) -> 107 | E19: =SUM(E7:E18) -> 0 | F19: =SUM(F7:F18) -> 10 | G19: =SUM(G7:G18) -> 10 | H19: =SUM(H7:H18) -> 10 | I19: =SUM(I7:I18) -> 10 | J19: =SUM(J7:J18) -> 10 | K19: =SUM(K7:K18) -> 10 | L19: =SUM(L7:L18) -> 10 | ... HH19: =SUM(HH7:HH18) -> 0
A20: BUGGIES
A21: ='FY1 Event Pipeline'!A4 -> Saadiyat Nights | B21: =_xlfn.XLOOKUP(A21,'FY1 Event Pipeline'!$A$4:$A$15,'FY1 Event Pipeline'!$H$4:$H$15) -> 46297 | C21: =_xlfn.XLOOKUP(A21,'FY1 Event Pipeline'!$A$4:$A$15,'FY1 Event Pipeline'!$J$4:$J$15) -> 46453 | D21: =_xlfn.XLOOKUP(A21,'FY1 Event Pipeline'!$A$4:$A$15,'FY1 Event Pipeline'!$O$4:$O$15) -> 10 | E21: =IF(AND(E$5>=$B21,E$5<=$C21),$D21,"") | F21: =IF(AND(F$5>=$B21,F$5<=$C21),$D21,"") -> 10 | G21: =IF(AND(G$5>=$B21,G$5<=$C21),$D21,"") -> 10 | H21: =IF(AND(H$5>=$B21,H$5<=$C21),$D21,"") -> 10 | I21: =IF(AND(I$5>=$B21,I$5<=$C21),$D21,"") -> 10 | J21: =IF(AND(J$5>=$B21,J$5<=$C21),$D21,"") -> 10 | K21: =IF(AND(K$5>=$B21,K$5<=$C21),$D21,"") -> 10 | L21: =IF(AND(L$5>=$B21,L$5<=$C21),$D21,"") -> 10 | ... HH21: =IF(AND(HH$5>=$B21,HH$5<=$C21),$D21,"")
A22: ='FY1 Event Pipeline'!A5 -> BRED X | B22: =_xlfn.XLOOKUP(A22,'FY1 Event Pipeline'!$A$4:$A$15,'FY1 Event Pipeline'!$H$4:$H$15) -> 46318 | C22: =_xlfn.XLOOKUP(A22,'FY1 Event Pipeline'!$A$4:$A$15,'FY1 Event Pipeline'!$J$4:$J$15) -> 46339 | D22: =_xlfn.XLOOKUP(A22,'FY1 Event Pipeline'!$A$4:$A$15,'FY1 Event Pipeline'!$O$4:$O$15) -> 0 | E22: =IF(AND(E$5>=$B22,E$5<=$C22),$D22,"") | F22: =IF(AND(F$5>=$B22,F$5<=$C22),$D22,"") | G22: =IF(AND(G$5>=$B22,G$5<=$C22),$D22,"") | H22: =IF(AND(H$5>=$B22,H$5<=$C22),$D22,"") | I22: =IF(AND(I$5>=$B22,I$5<=$C22),$D22,"") | J22: =IF(AND(J$5>=$B22,J$5<=$C22),$D22,"") | K22: =IF(AND(K$5>=$B22,K$5<=$C22),$D22,"") | L22: =IF(AND(L$5>=$B22,L$5<=$C22),$D22,"") | ... HH22: =IF(AND(HH$5>=$B22,HH$5<=$C22),$D22,"")
A23: ='FY1 Event Pipeline'!A6 -> MOTN DHA | B23: =_xlfn.XLOOKUP(A23,'FY1 Event Pipeline'!$A$4:$A$15,'FY1 Event Pipeline'!$H$4:$H$15) -> 46330 | C23: =_xlfn.XLOOKUP(A23,'FY1 Event Pipeline'!$A$4:$A$15,'FY1 Event Pipeline'!$J$4:$J$15) -> 46352 | D23: =_xlfn.XLOOKUP(A23,'FY1 Event Pipeline'!$A$4:$A$15,'FY1 Event Pipeline'!$O$4:$O$15) -> 6 | E23: =IF(AND(E$5>=$B23,E$5<=$C23),$D23,"") | F23: =IF(AND(F$5>=$B23,F$5<=$C23),$D23,"") | G23: =IF(AND(G$5>=$B23,G$5<=$C23),$D23,"") | H23: =IF(AND(H$5>=$B23,H$5<=$C23),$D23,"") | I23: =IF(AND(I$5>=$B23,I$5<=$C23),$D23,"") | J23: =IF(AND(J$5>=$B23,J$5<=$C23),$D23,"") | K23: =IF(AND(K$5>=$B23,K$5<=$C23),$D23,"") | L23: =IF(AND(L$5>=$B23,L$5<=$C23),$D23,"") | ... HH23: =IF(AND(HH$5>=$B23,HH$5<=$C23),$D23,"")
A24: ='FY1 Event Pipeline'!A7 -> No Art UAE | B24: =_xlfn.XLOOKUP(A24,'FY1 Event Pipeline'!$A$4:$A$15,'FY1 Event Pipeline'!$H$4:$H$15) -> 46332 | C24: =_xlfn.XLOOKUP(A24,'FY1 Event Pipeline'!$A$4:$A$15,'FY1 Event Pipeline'!$J$4:$J$15) -> 46353 | D24: =_xlfn.XLOOKUP(A24,'FY1 Event Pipeline'!$A$4:$A$15,'FY1 Event Pipeline'!$O$4:$O$15) -> 6 | E24: =IF(AND(E$5>=$B24,E$5<=$C24),$D24,"") | F24: =IF(AND(F$5>=$B24,F$5<=$C24),$D24,"") | G24: =IF(AND(G$5>=$B24,G$5<=$C24),$D24,"") | H24: =IF(AND(H$5>=$B24,H$5<=$C24),$D24,"") | I24: =IF(AND(I$5>=$B24,I$5<=$C24),$D24,"") | J24: =IF(AND(J$5>=$B24,J$5<=$C24),$D24,"") | K24: =IF(AND(K$5>=$B24,K$5<=$C24),$D24,"") | L24: =IF(AND(L$5>=$B24,L$5<=$C24),$D24,"") | ... HH24: =IF(AND(HH$5>=$B24,HH$5<=$C24),$D24,"")
A25: ='FY1 Event Pipeline'!A8 -> Tanweer Festival | B25: =_xlfn.XLOOKUP(A25,'FY1 Event Pipeline'!$A$4:$A$15,'FY1 Event Pipeline'!$H$4:$H$15) -> 46340 | C25: =_xlfn.XLOOKUP(A25,'FY1 Event Pipeline'!$A$4:$A$15,'FY1 Event Pipeline'!$J$4:$J$15) -> 46352 | D25: =_xlfn.XLOOKUP(A25,'FY1 Event Pipeline'!$A$4:$A$15,'FY1 Event Pipeline'!$O$4:$O$15) -> 8 | E25: =IF(AND(E$5>=$B25,E$5<=$C25),$D25,"") | F25: =IF(AND(F$5>=$B25,F$5<=$C25),$D25,"") | G25: =IF(AND(G$5>=$B25,G$5<=$C25),$D25,"") | H25: =IF(AND(H$5>=$B25,H$5<=$C25),$D25,"") | I25: =IF(AND(I$5>=$B25,I$5<=$C25),$D25,"") | J25: =IF(AND(J$5>=$B25,J$5<=$C25),$D25,"") | K25: =IF(AND(K$5>=$B25,K$5<=$C25),$D25,"") | L25: =IF(AND(L$5>=$B25,L$5<=$C25),$D25,"") | ... HH25: =IF(AND(HH$5>=$B25,HH$5<=$C25),$D25,"")
A26: ='FY1 Event Pipeline'!A9 -> MOTN AAN | B26: =_xlfn.XLOOKUP(A26,'FY1 Event Pipeline'!$A$4:$A$15,'FY1 Event Pipeline'!$H$4:$H$15) -> 46336 | C26: =_xlfn.XLOOKUP(A26,'FY1 Event Pipeline'!$A$4:$A$15,'FY1 Event Pipeline'!$J$4:$J$15) -> 46362 | D26: =_xlfn.XLOOKUP(A26,'FY1 Event Pipeline'!$A$4:$A$15,'FY1 Event Pipeline'!$O$4:$O$15) -> 6 | E26: =IF(AND(E$5>=$B26,E$5<=$C26),$D26,"") | F26: =IF(AND(F$5>=$B26,F$5<=$C26),$D26,"") | G26: =IF(AND(G$5>=$B26,G$5<=$C26),$D26,"") | H26: =IF(AND(H$5>=$B26,H$5<=$C26),$D26,"") | I26: =IF(AND(I$5>=$B26,I$5<=$C26),$D26,"") | J26: =IF(AND(J$5>=$B26,J$5<=$C26),$D26,"") | K26: =IF(AND(K$5>=$B26,K$5<=$C26),$D26,"") | L26: =IF(AND(L$5>=$B26,L$5<=$C26),$D26,"") | ... HH26: =IF(AND(HH$5>=$B26,HH$5<=$C26),$D26,"")
A27: ='FY1 Event Pipeline'!A10 -> F1 Afterparty | B27: =_xlfn.XLOOKUP(A27,'FY1 Event Pipeline'!$A$4:$A$15,'FY1 Event Pipeline'!$H$4:$H$15) -> 46353 | C27: =_xlfn.XLOOKUP(A27,'FY1 Event Pipeline'!$A$4:$A$15,'FY1 Event Pipeline'!$J$4:$J$15) -> 46365 | D27: =_xlfn.XLOOKUP(A27,'FY1 Event Pipeline'!$A$4:$A$15,'FY1 Event Pipeline'!$O$4:$O$15) -> 8 | E27: =IF(AND(E$5>=$B27,E$5<=$C27),$D27,"") | F27: =IF(AND(F$5>=$B27,F$5<=$C27),$D27,"") | G27: =IF(AND(G$5>=$B27,G$5<=$C27),$D27,"") | H27: =IF(AND(H$5>=$B27,H$5<=$C27),$D27,"") | I27: =IF(AND(I$5>=$B27,I$5<=$C27),$D27,"") | J27: =IF(AND(J$5>=$B27,J$5<=$C27),$D27,"") | K27: =IF(AND(K$5>=$B27,K$5<=$C27),$D27,"") | L27: =IF(AND(L$5>=$B27,L$5<=$C27),$D27,"") | ... HH27: =IF(AND(HH$5>=$B27,HH$5<=$C27),$D27,"")
A28: ='FY1 Event Pipeline'!A11 -> MOTN AUH | B28: =_xlfn.XLOOKUP(A28,'FY1 Event Pipeline'!$A$4:$A$15,'FY1 Event Pipeline'!$H$4:$H$15) -> 46346 | C28: =_xlfn.XLOOKUP(A28,'FY1 Event Pipeline'!$A$4:$A$15,'FY1 Event Pipeline'!$J$4:$J$15) -> 46398 | D28: =_xlfn.XLOOKUP(A28,'FY1 Event Pipeline'!$A$4:$A$15,'FY1 Event Pipeline'!$O$4:$O$15) -> 10 | E28: =IF(AND(E$5>=$B28,E$5<=$C28),$D28,"") | F28: =IF(AND(F$5>=$B28,F$5<=$C28),$D28,"") | G28: =IF(AND(G$5>=$B28,G$5<=$C28),$D28,"") | H28: =IF(AND(H$5>=$B28,H$5<=$C28),$D28,"") | I28: =IF(AND(I$5>=$B28,I$5<=$C28),$D28,"") | J28: =IF(AND(J$5>=$B28,J$5<=$C28),$D28,"") | K28: =IF(AND(K$5>=$B28,K$5<=$C28),$D28,"") | L28: =IF(AND(L$5>=$B28,L$5<=$C28),$D28,"") | ... HH28: =IF(AND(HH$5>=$B28,HH$5<=$C28),$D28,"")
A29: ='FY1 Event Pipeline'!A12 -> Yas Winterfest | B29: =_xlfn.XLOOKUP(A29,'FY1 Event Pipeline'!$A$4:$A$15,'FY1 Event Pipeline'!$H$4:$H$15) -> 46352 | C29: =_xlfn.XLOOKUP(A29,'FY1 Event Pipeline'!$A$4:$A$15,'FY1 Event Pipeline'!$J$4:$J$15) -> 46384 | D29: =_xlfn.XLOOKUP(A29,'FY1 Event Pipeline'!$A$4:$A$15,'FY1 Event Pipeline'!$O$4:$O$15) -> 4 | E29: =IF(AND(E$5>=$B29,E$5<=$C29),$D29,"") | F29: =IF(AND(F$5>=$B29,F$5<=$C29),$D29,"") | G29: =IF(AND(G$5>=$B29,G$5<=$C29),$D29,"") | H29: =IF(AND(H$5>=$B29,H$5<=$C29),$D29,"") | I29: =IF(AND(I$5>=$B29,I$5<=$C29),$D29,"") | J29: =IF(AND(J$5>=$B29,J$5<=$C29),$D29,"") | K29: =IF(AND(K$5>=$B29,K$5<=$C29),$D29,"") | L29: =IF(AND(L$5>=$B29,L$5<=$C29),$D29,"") | ... HH29: =IF(AND(HH$5>=$B29,HH$5<=$C29),$D29,"")
A30: ='FY1 Event Pipeline'!A13 -> Animenia | B30: =_xlfn.XLOOKUP(A30,'FY1 Event Pipeline'!$A$4:$A$15,'FY1 Event Pipeline'!$H$4:$H$15) -> 46414 | C30: =_xlfn.XLOOKUP(A30,'FY1 Event Pipeline'!$A$4:$A$15,'FY1 Event Pipeline'!$J$4:$J$15) -> 46436 | D30: =_xlfn.XLOOKUP(A30,'FY1 Event Pipeline'!$A$4:$A$15,'FY1 Event Pipeline'!$O$4:$O$15) -> 4 | E30: =IF(AND(E$5>=$B30,E$5<=$C30),$D30,"") | F30: =IF(AND(F$5>=$B30,F$5<=$C30),$D30,"") | G30: =IF(AND(G$5>=$B30,G$5<=$C30),$D30,"") | H30: =IF(AND(H$5>=$B30,H$5<=$C30),$D30,"") | I30: =IF(AND(I$5>=$B30,I$5<=$C30),$D30,"") | J30: =IF(AND(J$5>=$B30,J$5<=$C30),$D30,"") | K30: =IF(AND(K$5>=$B30,K$5<=$C30),$D30,"") | L30: =IF(AND(L$5>=$B30,L$5<=$C30),$D30,"") | ... HH30: =IF(AND(HH$5>=$B30,HH$5<=$C30),$D30,"")
A31: ='FY1 Event Pipeline'!A14 -> DAZ | B31: =_xlfn.XLOOKUP(A31,'FY1 Event Pipeline'!$A$4:$A$15,'FY1 Event Pipeline'!$H$4:$H$15) -> 46466 | C31: =_xlfn.XLOOKUP(A31,'FY1 Event Pipeline'!$A$4:$A$15,'FY1 Event Pipeline'!$J$4:$J$15) -> 46496 | D31: =_xlfn.XLOOKUP(A31,'FY1 Event Pipeline'!$A$4:$A$15,'FY1 Event Pipeline'!$O$4:$O$15) -> 4 | E31: =IF(AND(E$5>=$B31,E$5<=$C31),$D31,"") | F31: =IF(AND(F$5>=$B31,F$5<=$C31),$D31,"") | G31: =IF(AND(G$5>=$B31,G$5<=$C31),$D31,"") | H31: =IF(AND(H$5>=$B31,H$5<=$C31),$D31,"") | I31: =IF(AND(I$5>=$B31,I$5<=$C31),$D31,"") | J31: =IF(AND(J$5>=$B31,J$5<=$C31),$D31,"") | K31: =IF(AND(K$5>=$B31,K$5<=$C31),$D31,"") | L31: =IF(AND(L$5>=$B31,L$5<=$C31),$D31,"") | ... HH31: =IF(AND(HH$5>=$B31,HH$5<=$C31),$D31,"")
A32: ='FY1 Event Pipeline'!A15 -> BRED | B32: =_xlfn.XLOOKUP(A32,'FY1 Event Pipeline'!$A$4:$A$15,'FY1 Event Pipeline'!$H$4:$H$15) -> 46492 | C32: =_xlfn.XLOOKUP(A32,'FY1 Event Pipeline'!$A$4:$A$15,'FY1 Event Pipeline'!$J$4:$J$15) -> 46506 | D32: =_xlfn.XLOOKUP(A32,'FY1 Event Pipeline'!$A$4:$A$15,'FY1 Event Pipeline'!$O$4:$O$15) -> 6 | E32: =IF(AND(E$5>=$B32,E$5<=$C32),$D32,"") | F32: =IF(AND(F$5>=$B32,F$5<=$C32),$D32,"") | G32: =IF(AND(G$5>=$B32,G$5<=$C32),$D32,"") | H32: =IF(AND(H$5>=$B32,H$5<=$C32),$D32,"") | I32: =IF(AND(I$5>=$B32,I$5<=$C32),$D32,"") | J32: =IF(AND(J$5>=$B32,J$5<=$C32),$D32,"") | K32: =IF(AND(K$5>=$B32,K$5<=$C32),$D32,"") | L32: =IF(AND(L$5>=$B32,L$5<=$C32),$D32,"") | ... HH32: =IF(AND(HH$5>=$B32,HH$5<=$C32),$D32,"")
A33: MAX BUGGIES ON-HIRE | D33: =MAX(F33:HH33) -> 50 | E33: =SUM(E21:E32) -> 0 | F33: =SUM(F21:F32) -> 10 | G33: =SUM(G21:G32) -> 10 | H33: =SUM(H21:H32) -> 10 | I33: =SUM(I21:I32) -> 10 | J33: =SUM(J21:J32) -> 10 | K33: =SUM(K21:K32) -> 10 | L33: =SUM(L21:L32) -> 10 | ... HH33: =SUM(HH21:HH32) -> 0
A34: BARRIERS
A35: ='FY1 Event Pipeline'!A4 -> Saadiyat Nights | B35: =_xlfn.XLOOKUP(A35,'FY1 Event Pipeline'!$A$4:$A$15,'FY1 Event Pipeline'!$H$4:$H$15) -> 46297 | C35: =_xlfn.XLOOKUP(A35,'FY1 Event Pipeline'!$A$4:$A$15,'FY1 Event Pipeline'!$J$4:$J$15) -> 46453 | D35: =_xlfn.XLOOKUP(A35,'FY1 Event Pipeline'!$A$4:$A$15,'FY1 Event Pipeline'!$P$4:$P$15) -> 0 | E35: =IF(AND(E$5>=$B35,E$5<=$C35),$D35,"") | F35: =IF(AND(F$5>=$B35,F$5<=$C35),$D35,"") -> 0 | G35: =IF(AND(G$5>=$B35,G$5<=$C35),$D35,"") -> 0 | H35: =IF(AND(H$5>=$B35,H$5<=$C35),$D35,"") -> 0 | I35: =IF(AND(I$5>=$B35,I$5<=$C35),$D35,"") -> 0 | J35: =IF(AND(J$5>=$B35,J$5<=$C35),$D35,"") -> 0 | K35: =IF(AND(K$5>=$B35,K$5<=$C35),$D35,"") -> 0 | L35: =IF(AND(L$5>=$B35,L$5<=$C35),$D35,"") -> 0 | ... HH35: =IF(AND(HH$5>=$B35,HH$5<=$C35),$D35,"")
A36: ='FY1 Event Pipeline'!A5 -> BRED X | B36: =_xlfn.XLOOKUP(A36,'FY1 Event Pipeline'!$A$4:$A$15,'FY1 Event Pipeline'!$H$4:$H$15) -> 46318 | C36: =_xlfn.XLOOKUP(A36,'FY1 Event Pipeline'!$A$4:$A$15,'FY1 Event Pipeline'!$J$4:$J$15) -> 46339 | D36: =_xlfn.XLOOKUP(A36,'FY1 Event Pipeline'!$A$4:$A$15,'FY1 Event Pipeline'!$P$4:$P$15) -> 0 | E36: =IF(AND(E$5>=$B36,E$5<=$C36),$D36,"") | F36: =IF(AND(F$5>=$B36,F$5<=$C36),$D36,"") | G36: =IF(AND(G$5>=$B36,G$5<=$C36),$D36,"") | H36: =IF(AND(H$5>=$B36,H$5<=$C36),$D36,"") | I36: =IF(AND(I$5>=$B36,I$5<=$C36),$D36,"") | J36: =IF(AND(J$5>=$B36,J$5<=$C36),$D36,"") | K36: =IF(AND(K$5>=$B36,K$5<=$C36),$D36,"") | L36: =IF(AND(L$5>=$B36,L$5<=$C36),$D36,"") | ... HH36: =IF(AND(HH$5>=$B36,HH$5<=$C36),$D36,"")
A37: ='FY1 Event Pipeline'!A6 -> MOTN DHA | B37: =_xlfn.XLOOKUP(A37,'FY1 Event Pipeline'!$A$4:$A$15,'FY1 Event Pipeline'!$H$4:$H$15) -> 46330 | C37: =_xlfn.XLOOKUP(A37,'FY1 Event Pipeline'!$A$4:$A$15,'FY1 Event Pipeline'!$J$4:$J$15) -> 46352 | D37: =_xlfn.XLOOKUP(A37,'FY1 Event Pipeline'!$A$4:$A$15,'FY1 Event Pipeline'!$P$4:$P$15) -> 350 | E37: =IF(AND(E$5>=$B37,E$5<=$C37),$D37,"") | F37: =IF(AND(F$5>=$B37,F$5<=$C37),$D37,"") | G37: =IF(AND(G$5>=$B37,G$5<=$C37),$D37,"") | H37: =IF(AND(H$5>=$B37,H$5<=$C37),$D37,"") | I37: =IF(AND(I$5>=$B37,I$5<=$C37),$D37,"") | J37: =IF(AND(J$5>=$B37,J$5<=$C37),$D37,"") | K37: =IF(AND(K$5>=$B37,K$5<=$C37),$D37,"") | L37: =IF(AND(L$5>=$B37,L$5<=$C37),$D37,"") | ... HH37: =IF(AND(HH$5>=$B37,HH$5<=$C37),$D37,"")
A38: ='FY1 Event Pipeline'!A7 -> No Art UAE | B38: =_xlfn.XLOOKUP(A38,'FY1 Event Pipeline'!$A$4:$A$15,'FY1 Event Pipeline'!$H$4:$H$15) -> 46332 | C38: =_xlfn.XLOOKUP(A38,'FY1 Event Pipeline'!$A$4:$A$15,'FY1 Event Pipeline'!$J$4:$J$15) -> 46353 | D38: =_xlfn.XLOOKUP(A38,'FY1 Event Pipeline'!$A$4:$A$15,'FY1 Event Pipeline'!$P$4:$P$15) -> 0 | E38: =IF(AND(E$5>=$B38,E$5<=$C38),$D38,"") | F38: =IF(AND(F$5>=$B38,F$5<=$C38),$D38,"") | G38: =IF(AND(G$5>=$B38,G$5<=$C38),$D38,"") | H38: =IF(AND(H$5>=$B38,H$5<=$C38),$D38,"") | I38: =IF(AND(I$5>=$B38,I$5<=$C38),$D38,"") | J38: =IF(AND(J$5>=$B38,J$5<=$C38),$D38,"") | K38: =IF(AND(K$5>=$B38,K$5<=$C38),$D38,"") | L38: =IF(AND(L$5>=$B38,L$5<=$C38),$D38,"") | ... HH38: =IF(AND(HH$5>=$B38,HH$5<=$C38),$D38,"")
A39: ='FY1 Event Pipeline'!A8 -> Tanweer Festival | B39: =_xlfn.XLOOKUP(A39,'FY1 Event Pipeline'!$A$4:$A$15,'FY1 Event Pipeline'!$H$4:$H$15) -> 46340 | C39: =_xlfn.XLOOKUP(A39,'FY1 Event Pipeline'!$A$4:$A$15,'FY1 Event Pipeline'!$J$4:$J$15) -> 46352 | D39: =_xlfn.XLOOKUP(A39,'FY1 Event Pipeline'!$A$4:$A$15,'FY1 Event Pipeline'!$P$4:$P$15) -> 900 | E39: =IF(AND(E$5>=$B39,E$5<=$C39),$D39,"") | F39: =IF(AND(F$5>=$B39,F$5<=$C39),$D39,"") | G39: =IF(AND(G$5>=$B39,G$5<=$C39),$D39,"") | H39: =IF(AND(H$5>=$B39,H$5<=$C39),$D39,"") | I39: =IF(AND(I$5>=$B39,I$5<=$C39),$D39,"") | J39: =IF(AND(J$5>=$B39,J$5<=$C39),$D39,"") | K39: =IF(AND(K$5>=$B39,K$5<=$C39),$D39,"") | L39: =IF(AND(L$5>=$B39,L$5<=$C39),$D39,"") | ... HH39: =IF(AND(HH$5>=$B39,HH$5<=$C39),$D39,"")
A40: ='FY1 Event Pipeline'!A9 -> MOTN AAN | B40: =_xlfn.XLOOKUP(A40,'FY1 Event Pipeline'!$A$4:$A$15,'FY1 Event Pipeline'!$H$4:$H$15) -> 46336 | C40: =_xlfn.XLOOKUP(A40,'FY1 Event Pipeline'!$A$4:$A$15,'FY1 Event Pipeline'!$J$4:$J$15) -> 46362 | D40: =_xlfn.XLOOKUP(A40,'FY1 Event Pipeline'!$A$4:$A$15,'FY1 Event Pipeline'!$P$4:$P$15) -> 350 | E40: =IF(AND(E$5>=$B40,E$5<=$C40),$D40,"") | F40: =IF(AND(F$5>=$B40,F$5<=$C40),$D40,"") | G40: =IF(AND(G$5>=$B40,G$5<=$C40),$D40,"") | H40: =IF(AND(H$5>=$B40,H$5<=$C40),$D40,"") | I40: =IF(AND(I$5>=$B40,I$5<=$C40),$D40,"") | J40: =IF(AND(J$5>=$B40,J$5<=$C40),$D40,"") | K40: =IF(AND(K$5>=$B40,K$5<=$C40),$D40,"") | L40: =IF(AND(L$5>=$B40,L$5<=$C40),$D40,"") | ... HH40: =IF(AND(HH$5>=$B40,HH$5<=$C40),$D40,"")
...

Sheet Depreciation Schedule
A1: STRAIGHT-LINE DEPRECIATION SCHEDULE
A2: Each capex tranche depreciated independently from acquisition year. CapEx pulled from CapEx & Storage sheet.
A3: Asset Group | B3: CapEx (AED) | C3: Acquisition Year | D3: Life (yrs) | E3: Residual % | F3: Depreciable Base | G3: Annual Dep'n | H3: Year 1 | I3: Year 2 | J3: Year 3 | K3: Year 4 | L3: Year 5 | M3: Year 6 | N3: Year 7 | O3: Year 8
H4: 1 | I4: 2 | J4: 3 | K4: 4 | L4: 5 | M4: 6 | N4: 7 | O4: 8
